[Wed Oct 12 15:36:02.017946 2022] [authz_core:error] [pid 9788:tid 1880] [client ::1:15385] AH01630: client denied by server configuration: E:/Python_project/CharterIns/CharterIns/wsgi.py
[Wed Oct 12 16:37:14.875458 2022] [wsgi:error] [pid 9816:tid 1884] [client ::1:16232] mod_wsgi (pid=9816): Failed to exec Python script file 'E:/Python_project/A_Jalil_S_M/A_Jalil_S_M/wsgi.py'.
[Wed Oct 12 16:37:14.875458 2022] [wsgi:error] [pid 9816:tid 1884] [client ::1:16232] mod_wsgi (pid=9816): Exception occurred processing WSGI script 'E:/Python_project/A_Jalil_S_M/A_Jalil_S_M/wsgi.py'.
[Wed Oct 12 16:37:14.915460 2022] [wsgi:error] [pid 9816:tid 1884] [client ::1:16232] Traceback (most recent call last):\r
[Wed Oct 12 16:37:14.915460 2022] [wsgi:error] [pid 9816:tid 1884] [client ::1:16232]   File "C:\\Users\\Administrator\\AppData\\Local\\Programs\\Python\\Python310\\lib\\site-packages\\django\\apps\\registry.py", line 158, in get_app_config\r
[Wed Oct 12 16:37:14.915460 2022] [wsgi:error] [pid 9816:tid 1884] [client ::1:16232]     return self.app_configs[app_label]\r
[Wed Oct 12 16:37:14.915460 2022] [wsgi:error] [pid 9816:tid 1884] [client ::1:16232] KeyError: 'PersonalInfo'\r
[Wed Oct 12 16:37:14.915460 2022] [wsgi:error] [pid 9816:tid 1884] [client ::1:16232] \r
[Wed Oct 12 16:37:14.915460 2022] [wsgi:error] [pid 9816:tid 1884] [client ::1:16232] During handling of the above exception, another exception occurred:\r
[Wed Oct 12 16:37:14.915460 2022] [wsgi:error] [pid 9816:tid 1884] [client ::1:16232] \r
[Wed Oct 12 16:37:14.915460 2022] [wsgi:error] [pid 9816:tid 1884] [client ::1:16232] Traceback (most recent call last):\r
[Wed Oct 12 16:37:14.915460 2022] [wsgi:error] [pid 9816:tid 1884] [client ::1:16232]   File "C:\\Users\\Administrator\\AppData\\Local\\Programs\\Python\\Python310\\lib\\site-packages\\django\\contrib\\auth\\__init__.py", line 170, in get_user_model\r
[Wed Oct 12 16:37:14.915460 2022] [wsgi:error] [pid 9816:tid 1884] [client ::1:16232]     return django_apps.get_model(settings.AUTH_USER_MODEL, require_ready=False)\r
[Wed Oct 12 16:37:14.915460 2022] [wsgi:error] [pid 9816:tid 1884] [client ::1:16232]   File "C:\\Users\\Administrator\\AppData\\Local\\Programs\\Python\\Python310\\lib\\site-packages\\django\\apps\\registry.py", line 208, in get_model\r
[Wed Oct 12 16:37:14.915460 2022] [wsgi:error] [pid 9816:tid 1884] [client ::1:16232]     app_config = self.get_app_config(app_label)\r
[Wed Oct 12 16:37:14.915460 2022] [wsgi:error] [pid 9816:tid 1884] [client ::1:16232]   File "C:\\Users\\Administrator\\AppData\\Local\\Programs\\Python\\Python310\\lib\\site-packages\\django\\apps\\registry.py", line 165, in get_app_config\r
[Wed Oct 12 16:37:14.915460 2022] [wsgi:error] [pid 9816:tid 1884] [client ::1:16232]     raise LookupError(message)\r
[Wed Oct 12 16:37:14.915460 2022] [wsgi:error] [pid 9816:tid 1884] [client ::1:16232] LookupError: No installed app with label 'PersonalInfo'.\r
[Wed Oct 12 16:37:14.915460 2022] [wsgi:error] [pid 9816:tid 1884] [client ::1:16232] \r
[Wed Oct 12 16:37:14.915460 2022] [wsgi:error] [pid 9816:tid 1884] [client ::1:16232] During handling of the above exception, another exception occurred:\r
[Wed Oct 12 16:37:14.915460 2022] [wsgi:error] [pid 9816:tid 1884] [client ::1:16232] \r
[Wed Oct 12 16:37:14.915460 2022] [wsgi:error] [pid 9816:tid 1884] [client ::1:16232] Traceback (most recent call last):\r
[Wed Oct 12 16:37:14.915460 2022] [wsgi:error] [pid 9816:tid 1884] [client ::1:16232]   File "E:/Python_project/A_Jalil_S_M/A_Jalil_S_M/wsgi.py", line 14, in <module>\r
[Wed Oct 12 16:37:14.915460 2022] [wsgi:error] [pid 9816:tid 1884] [client ::1:16232]     application = get_wsgi_application()\r
[Wed Oct 12 16:37:14.915460 2022] [wsgi:error] [pid 9816:tid 1884] [client ::1:16232]   File "C:\\Users\\Administrator\\AppData\\Local\\Programs\\Python\\Python310\\lib\\site-packages\\django\\core\\wsgi.py", line 12, in get_wsgi_application\r
[Wed Oct 12 16:37:14.915460 2022] [wsgi:error] [pid 9816:tid 1884] [client ::1:16232]     django.setup(set_prefix=False)\r
[Wed Oct 12 16:37:14.915460 2022] [wsgi:error] [pid 9816:tid 1884] [client ::1:16232]   File "C:\\Users\\Administrator\\AppData\\Local\\Programs\\Python\\Python310\\lib\\site-packages\\django\\__init__.py", line 24, in setup\r
[Wed Oct 12 16:37:14.915460 2022] [wsgi:error] [pid 9816:tid 1884] [client ::1:16232]     apps.populate(settings.INSTALLED_APPS)\r
[Wed Oct 12 16:37:14.915460 2022] [wsgi:error] [pid 9816:tid 1884] [client ::1:16232]   File "C:\\Users\\Administrator\\AppData\\Local\\Programs\\Python\\Python310\\lib\\site-packages\\django\\apps\\registry.py", line 124, in populate\r
[Wed Oct 12 16:37:14.915460 2022] [wsgi:error] [pid 9816:tid 1884] [client ::1:16232]     app_config.ready()\r
[Wed Oct 12 16:37:14.915460 2022] [wsgi:error] [pid 9816:tid 1884] [client ::1:16232]   File "C:\\Users\\Administrator\\AppData\\Local\\Programs\\Python\\Python310\\lib\\site-packages\\django\\contrib\\admin\\apps.py", line 27, in ready\r
[Wed Oct 12 16:37:14.915460 2022] [wsgi:error] [pid 9816:tid 1884] [client ::1:16232]     self.module.autodiscover()\r
[Wed Oct 12 16:37:14.915460 2022] [wsgi:error] [pid 9816:tid 1884] [client ::1:16232]   File "C:\\Users\\Administrator\\AppData\\Local\\Programs\\Python\\Python310\\lib\\site-packages\\django\\contrib\\admin\\__init__.py", line 50, in autodiscover\r
[Wed Oct 12 16:37:14.915460 2022] [wsgi:error] [pid 9816:tid 1884] [client ::1:16232]     autodiscover_modules("admin", register_to=site)\r
[Wed Oct 12 16:37:14.915460 2022] [wsgi:error] [pid 9816:tid 1884] [client ::1:16232]   File "C:\\Users\\Administrator\\AppData\\Local\\Programs\\Python\\Python310\\lib\\site-packages\\django\\utils\\module_loading.py", line 58, in autodiscover_modules\r
[Wed Oct 12 16:37:14.915460 2022] [wsgi:error] [pid 9816:tid 1884] [client ::1:16232]     import_module("%s.%s" % (app_config.name, module_to_search))\r
[Wed Oct 12 16:37:14.915460 2022] [wsgi:error] [pid 9816:tid 1884] [client ::1:16232]   File "C:\\Users\\Administrator\\AppData\\Local\\Programs\\Python\\Python310\\Lib\\importlib\\__init__.py", line 126, in import_module\r
[Wed Oct 12 16:37:14.915460 2022] [wsgi:error] [pid 9816:tid 1884] [client ::1:16232]     return _bootstrap._gcd_import(name[level:], package, level)\r
[Wed Oct 12 16:37:14.915460 2022] [wsgi:error] [pid 9816:tid 1884] [client ::1:16232]   File "<frozen importlib._bootstrap>", line 1050, in _gcd_import\r
[Wed Oct 12 16:37:14.915460 2022] [wsgi:error] [pid 9816:tid 1884] [client ::1:16232]   File "<frozen importlib._bootstrap>", line 1027, in _find_and_load\r
[Wed Oct 12 16:37:14.915460 2022] [wsgi:error] [pid 9816:tid 1884] [client ::1:16232]   File "<frozen importlib._bootstrap>", line 1006, in _find_and_load_unlocked\r
[Wed Oct 12 16:37:14.915460 2022] [wsgi:error] [pid 9816:tid 1884] [client ::1:16232]   File "<frozen importlib._bootstrap>", line 688, in _load_unlocked\r
[Wed Oct 12 16:37:14.916460 2022] [wsgi:error] [pid 9816:tid 1884] [client ::1:16232]   File "<frozen importlib._bootstrap_external>", line 883, in exec_module\r
[Wed Oct 12 16:37:14.916460 2022] [wsgi:error] [pid 9816:tid 1884] [client ::1:16232]   File "<frozen importlib._bootstrap>", line 241, in _call_with_frames_removed\r
[Wed Oct 12 16:37:14.916460 2022] [wsgi:error] [pid 9816:tid 1884] [client ::1:16232]   File "C:\\Users\\Administrator\\AppData\\Local\\Programs\\Python\\Python310\\lib\\site-packages\\django\\contrib\\auth\\admin.py", line 6, in <module>\r
[Wed Oct 12 16:37:14.916460 2022] [wsgi:error] [pid 9816:tid 1884] [client ::1:16232]     from django.contrib.auth.forms import (\r
[Wed Oct 12 16:37:14.916460 2022] [wsgi:error] [pid 9816:tid 1884] [client ::1:16232]   File "C:\\Users\\Administrator\\AppData\\Local\\Programs\\Python\\Python310\\lib\\site-packages\\django\\contrib\\auth\\forms.py", line 18, in <module>\r
[Wed Oct 12 16:37:14.916460 2022] [wsgi:error] [pid 9816:tid 1884] [client ::1:16232]     UserModel = get_user_model()\r
[Wed Oct 12 16:37:14.916460 2022] [wsgi:error] [pid 9816:tid 1884] [client ::1:16232]   File "C:\\Users\\Administrator\\AppData\\Local\\Programs\\Python\\Python310\\lib\\site-packages\\django\\contrib\\auth\\__init__.py", line 176, in get_user_model\r
[Wed Oct 12 16:37:14.916460 2022] [wsgi:error] [pid 9816:tid 1884] [client ::1:16232]     raise ImproperlyConfigured(\r
[Wed Oct 12 16:37:14.916460 2022] [wsgi:error] [pid 9816:tid 1884] [client ::1:16232] django.core.exceptions.ImproperlyConfigured: AUTH_USER_MODEL refers to model 'PersonalInfo.User' that has not been installed\r
[Wed Oct 12 16:37:17.845797 2022] [wsgi:error] [pid 9816:tid 1876] [client ::1:16237] mod_wsgi (pid=9816): Failed to exec Python script file 'E:/Python_project/A_Jalil_S_M/A_Jalil_S_M/wsgi.py'.
[Wed Oct 12 16:37:17.845797 2022] [wsgi:error] [pid 9816:tid 1876] [client ::1:16237] mod_wsgi (pid=9816): Exception occurred processing WSGI script 'E:/Python_project/A_Jalil_S_M/A_Jalil_S_M/wsgi.py'.
[Wed Oct 12 16:37:17.849798 2022] [wsgi:error] [pid 9816:tid 1876] [client ::1:16237] Traceback (most recent call last):\r
[Wed Oct 12 16:37:17.849798 2022] [wsgi:error] [pid 9816:tid 1876] [client ::1:16237]   File "E:/Python_project/A_Jalil_S_M/A_Jalil_S_M/wsgi.py", line 14, in <module>\r
[Wed Oct 12 16:37:17.849798 2022] [wsgi:error] [pid 9816:tid 1876] [client ::1:16237]     application = get_wsgi_application()\r
[Wed Oct 12 16:37:17.849798 2022] [wsgi:error] [pid 9816:tid 1876] [client ::1:16237]   File "C:\\Users\\Administrator\\AppData\\Local\\Programs\\Python\\Python310\\lib\\site-packages\\django\\core\\wsgi.py", line 12, in get_wsgi_application\r
[Wed Oct 12 16:37:17.849798 2022] [wsgi:error] [pid 9816:tid 1876] [client ::1:16237]     django.setup(set_prefix=False)\r
[Wed Oct 12 16:37:17.849798 2022] [wsgi:error] [pid 9816:tid 1876] [client ::1:16237]   File "C:\\Users\\Administrator\\AppData\\Local\\Programs\\Python\\Python310\\lib\\site-packages\\django\\__init__.py", line 24, in setup\r
[Wed Oct 12 16:37:17.849798 2022] [wsgi:error] [pid 9816:tid 1876] [client ::1:16237]     apps.populate(settings.INSTALLED_APPS)\r
[Wed Oct 12 16:37:17.849798 2022] [wsgi:error] [pid 9816:tid 1876] [client ::1:16237]   File "C:\\Users\\Administrator\\AppData\\Local\\Programs\\Python\\Python310\\lib\\site-packages\\django\\apps\\registry.py", line 83, in populate\r
[Wed Oct 12 16:37:17.849798 2022] [wsgi:error] [pid 9816:tid 1876] [client ::1:16237]     raise RuntimeError("populate() isn't reentrant")\r
[Wed Oct 12 16:37:17.849798 2022] [wsgi:error] [pid 9816:tid 1876] [client ::1:16237] RuntimeError: populate() isn't reentrant\r
[Thu Oct 13 12:04:09.655315 2022] [wsgi:error] [pid 8604:tid 1872] [client 192.168.94.110:52569] 01937148058\r, referer: http://10.99.99.201:8012/fd/personal_info
[Thu Oct 13 12:04:16.320200 2022] [wsgi:error] [pid 8604:tid 1872] [client 192.168.94.110:52569] 01937148058\r, referer: http://10.99.99.201:8012/fd/income
[Thu Oct 13 12:08:11.361482 2022] [wsgi:error] [pid 8604:tid 1872] [client 192.168.94.110:53058] Internal Server Error: /fd/image_request\r, referer: http://10.99.99.201:8012/fd/income
[Thu Oct 13 12:08:11.361482 2022] [wsgi:error] [pid 8604:tid 1872] [client 192.168.94.110:53058] Traceback (most recent call last):\r, referer: http://10.99.99.201:8012/fd/income
[Thu Oct 13 12:08:11.361482 2022] [wsgi:error] [pid 8604:tid 1872] [client 192.168.94.110:53058]   File "E:\\Python_project\\CharterIns\\venv\\Lib\\site-packages\\django\\core\\handlers\\exception.py", line 55, in inner\r, referer: http://10.99.99.201:8012/fd/income
[Thu Oct 13 12:08:11.361482 2022] [wsgi:error] [pid 8604:tid 1872] [client 192.168.94.110:53058]     response = get_response(request)\r, referer: http://10.99.99.201:8012/fd/income
[Thu Oct 13 12:08:11.361482 2022] [wsgi:error] [pid 8604:tid 1872] [client 192.168.94.110:53058]   File "E:\\Python_project\\CharterIns\\venv\\Lib\\site-packages\\django\\core\\handlers\\base.py", line 197, in _get_response\r, referer: http://10.99.99.201:8012/fd/income
[Thu Oct 13 12:08:11.361482 2022] [wsgi:error] [pid 8604:tid 1872] [client 192.168.94.110:53058]     response = wrapped_callback(request, *callback_args, **callback_kwargs)\r, referer: http://10.99.99.201:8012/fd/income
[Thu Oct 13 12:08:11.361482 2022] [wsgi:error] [pid 8604:tid 1872] [client 192.168.94.110:53058]   File "E:\\Python_project\\CharterIns\\venv\\Lib\\site-packages\\django\\contrib\\auth\\decorators.py", line 23, in _wrapped_view\r, referer: http://10.99.99.201:8012/fd/income
[Thu Oct 13 12:08:11.361482 2022] [wsgi:error] [pid 8604:tid 1872] [client 192.168.94.110:53058]     return view_func(request, *args, **kwargs)\r, referer: http://10.99.99.201:8012/fd/income
[Thu Oct 13 12:08:11.361482 2022] [wsgi:error] [pid 8604:tid 1872] [client 192.168.94.110:53058]   File "E:\\Python_project\\A_Jalil_S_M-master\\PersonalInfo\\views.py", line 248, in image_request\r, referer: http://10.99.99.201:8012/fd/income
[Thu Oct 13 12:08:11.361482 2022] [wsgi:error] [pid 8604:tid 1872] [client 192.168.94.110:53058]     return render(request, 'image_form.html', {'form': form, 'img_obj': img_object})\r, referer: http://10.99.99.201:8012/fd/income
[Thu Oct 13 12:08:11.361482 2022] [wsgi:error] [pid 8604:tid 1872] [client 192.168.94.110:53058]   File "E:\\Python_project\\CharterIns\\venv\\Lib\\site-packages\\django\\shortcuts.py", line 24, in render\r, referer: http://10.99.99.201:8012/fd/income
[Thu Oct 13 12:08:11.361482 2022] [wsgi:error] [pid 8604:tid 1872] [client 192.168.94.110:53058]     content = loader.render_to_string(template_name, context, request, using=using)\r, referer: http://10.99.99.201:8012/fd/income
[Thu Oct 13 12:08:11.361482 2022] [wsgi:error] [pid 8604:tid 1872] [client 192.168.94.110:53058]   File "E:\\Python_project\\CharterIns\\venv\\Lib\\site-packages\\django\\template\\loader.py", line 62, in render_to_string\r, referer: http://10.99.99.201:8012/fd/income
[Thu Oct 13 12:08:11.361482 2022] [wsgi:error] [pid 8604:tid 1872] [client 192.168.94.110:53058]     return template.render(context, request)\r, referer: http://10.99.99.201:8012/fd/income
[Thu Oct 13 12:08:11.361482 2022] [wsgi:error] [pid 8604:tid 1872] [client 192.168.94.110:53058]   File "E:\\Python_project\\CharterIns\\venv\\Lib\\site-packages\\django\\template\\backends\\django.py", line 62, in render\r, referer: http://10.99.99.201:8012/fd/income
[Thu Oct 13 12:08:11.361482 2022] [wsgi:error] [pid 8604:tid 1872] [client 192.168.94.110:53058]     return self.template.render(context)\r, referer: http://10.99.99.201:8012/fd/income
[Thu Oct 13 12:08:11.361482 2022] [wsgi:error] [pid 8604:tid 1872] [client 192.168.94.110:53058]   File "E:\\Python_project\\CharterIns\\venv\\Lib\\site-packages\\django\\template\\base.py", line 175, in render\r, referer: http://10.99.99.201:8012/fd/income
[Thu Oct 13 12:08:11.361482 2022] [wsgi:error] [pid 8604:tid 1872] [client 192.168.94.110:53058]     return self._render(context)\r, referer: http://10.99.99.201:8012/fd/income
[Thu Oct 13 12:08:11.361482 2022] [wsgi:error] [pid 8604:tid 1872] [client 192.168.94.110:53058]   File "E:\\Python_project\\CharterIns\\venv\\Lib\\site-packages\\django\\template\\base.py", line 167, in _render\r, referer: http://10.99.99.201:8012/fd/income
[Thu Oct 13 12:08:11.361482 2022] [wsgi:error] [pid 8604:tid 1872] [client 192.168.94.110:53058]     return self.nodelist.render(context)\r, referer: http://10.99.99.201:8012/fd/income
[Thu Oct 13 12:08:11.361482 2022] [wsgi:error] [pid 8604:tid 1872] [client 192.168.94.110:53058]   File "E:\\Python_project\\CharterIns\\venv\\Lib\\site-packages\\django\\template\\base.py", line 1000, in render\r, referer: http://10.99.99.201:8012/fd/income
[Thu Oct 13 12:08:11.361482 2022] [wsgi:error] [pid 8604:tid 1872] [client 192.168.94.110:53058]     return SafeString("".join([node.render_annotated(context) for node in self]))\r, referer: http://10.99.99.201:8012/fd/income
[Thu Oct 13 12:08:11.361482 2022] [wsgi:error] [pid 8604:tid 1872] [client 192.168.94.110:53058]   File "E:\\Python_project\\CharterIns\\venv\\Lib\\site-packages\\django\\template\\base.py", line 1000, in <listcomp>\r, referer: http://10.99.99.201:8012/fd/income
[Thu Oct 13 12:08:11.361482 2022] [wsgi:error] [pid 8604:tid 1872] [client 192.168.94.110:53058]     return SafeString("".join([node.render_annotated(context) for node in self]))\r, referer: http://10.99.99.201:8012/fd/income
[Thu Oct 13 12:08:11.361482 2022] [wsgi:error] [pid 8604:tid 1872] [client 192.168.94.110:53058]   File "E:\\Python_project\\CharterIns\\venv\\Lib\\site-packages\\django\\template\\base.py", line 958, in render_annotated\r, referer: http://10.99.99.201:8012/fd/income
[Thu Oct 13 12:08:11.361482 2022] [wsgi:error] [pid 8604:tid 1872] [client 192.168.94.110:53058]     return self.render(context)\r, referer: http://10.99.99.201:8012/fd/income
[Thu Oct 13 12:08:11.361482 2022] [wsgi:error] [pid 8604:tid 1872] [client 192.168.94.110:53058]   File "E:\\Python_project\\CharterIns\\venv\\Lib\\site-packages\\django\\template\\loader_tags.py", line 157, in render\r, referer: http://10.99.99.201:8012/fd/income
[Thu Oct 13 12:08:11.361482 2022] [wsgi:error] [pid 8604:tid 1872] [client 192.168.94.110:53058]     return compiled_parent._render(context)\r, referer: http://10.99.99.201:8012/fd/income
[Thu Oct 13 12:08:11.361482 2022] [wsgi:error] [pid 8604:tid 1872] [client 192.168.94.110:53058]   File "E:\\Python_project\\CharterIns\\venv\\Lib\\site-packages\\django\\template\\base.py", line 167, in _render\r, referer: http://10.99.99.201:8012/fd/income
[Thu Oct 13 12:08:11.361482 2022] [wsgi:error] [pid 8604:tid 1872] [client 192.168.94.110:53058]     return self.nodelist.render(context)\r, referer: http://10.99.99.201:8012/fd/income
[Thu Oct 13 12:08:11.361482 2022] [wsgi:error] [pid 8604:tid 1872] [client 192.168.94.110:53058]   File "E:\\Python_project\\CharterIns\\venv\\Lib\\site-packages\\django\\template\\base.py", line 1000, in render\r, referer: http://10.99.99.201:8012/fd/income
[Thu Oct 13 12:08:11.361482 2022] [wsgi:error] [pid 8604:tid 1872] [client 192.168.94.110:53058]     return SafeString("".join([node.render_annotated(context) for node in self]))\r, referer: http://10.99.99.201:8012/fd/income
[Thu Oct 13 12:08:11.361482 2022] [wsgi:error] [pid 8604:tid 1872] [client 192.168.94.110:53058]   File "E:\\Python_project\\CharterIns\\venv\\Lib\\site-packages\\django\\template\\base.py", line 1000, in <listcomp>\r, referer: http://10.99.99.201:8012/fd/income
[Thu Oct 13 12:08:11.362482 2022] [wsgi:error] [pid 8604:tid 1872] [client 192.168.94.110:53058]     return SafeString("".join([node.render_annotated(context) for node in self]))\r, referer: http://10.99.99.201:8012/fd/income
[Thu Oct 13 12:08:11.362482 2022] [wsgi:error] [pid 8604:tid 1872] [client 192.168.94.110:53058]   File "E:\\Python_project\\CharterIns\\venv\\Lib\\site-packages\\django\\template\\base.py", line 958, in render_annotated\r, referer: http://10.99.99.201:8012/fd/income
[Thu Oct 13 12:08:11.362482 2022] [wsgi:error] [pid 8604:tid 1872] [client 192.168.94.110:53058]     return self.render(context)\r, referer: http://10.99.99.201:8012/fd/income
[Thu Oct 13 12:08:11.362482 2022] [wsgi:error] [pid 8604:tid 1872] [client 192.168.94.110:53058]   File "E:\\Python_project\\CharterIns\\venv\\Lib\\site-packages\\django\\template\\defaulttags.py", line 472, in render\r, referer: http://10.99.99.201:8012/fd/income
[Thu Oct 13 12:08:11.362482 2022] [wsgi:error] [pid 8604:tid 1872] [client 192.168.94.110:53058]     url = reverse(view_name, args=args, kwargs=kwargs, current_app=current_app)\r, referer: http://10.99.99.201:8012/fd/income
[Thu Oct 13 12:08:11.362482 2022] [wsgi:error] [pid 8604:tid 1872] [client 192.168.94.110:53058]   File "E:\\Python_project\\CharterIns\\venv\\Lib\\site-packages\\django\\urls\\base.py", line 88, in reverse\r, referer: http://10.99.99.201:8012/fd/income
[Thu Oct 13 12:08:11.362482 2022] [wsgi:error] [pid 8604:tid 1872] [client 192.168.94.110:53058]     return resolver._reverse_with_prefix(view, prefix, *args, **kwargs)\r, referer: http://10.99.99.201:8012/fd/income
[Thu Oct 13 12:08:11.362482 2022] [wsgi:error] [pid 8604:tid 1872] [client 192.168.94.110:53058]   File "E:\\Python_project\\CharterIns\\venv\\Lib\\site-packages\\django\\urls\\resolvers.py", line 802, in _reverse_with_prefix\r, referer: http://10.99.99.201:8012/fd/income
[Thu Oct 13 12:08:11.362482 2022] [wsgi:error] [pid 8604:tid 1872] [client 192.168.94.110:53058]     raise NoReverseMatch(msg)\r, referer: http://10.99.99.201:8012/fd/income
[Thu Oct 13 12:08:11.362482 2022] [wsgi:error] [pid 8604:tid 1872] [client 192.168.94.110:53058] django.urls.exceptions.NoReverseMatch: Reverse for 'files_upload' not found. 'files_upload' is not a valid view function or pattern name.\r, referer: http://10.99.99.201:8012/fd/income
[Thu Oct 13 12:08:32.931013 2022] [wsgi:error] [pid 8604:tid 1872] [client 192.168.94.110:53080] Internal Server Error: /fd/landing\r, referer: http://10.99.99.201:8012/fd
[Thu Oct 13 12:08:32.931013 2022] [wsgi:error] [pid 8604:tid 1872] [client 192.168.94.110:53080] Traceback (most recent call last):\r, referer: http://10.99.99.201:8012/fd
[Thu Oct 13 12:08:32.931013 2022] [wsgi:error] [pid 8604:tid 1872] [client 192.168.94.110:53080]   File "E:\\Python_project\\CharterIns\\venv\\Lib\\site-packages\\django\\core\\handlers\\exception.py", line 55, in inner\r, referer: http://10.99.99.201:8012/fd
[Thu Oct 13 12:08:32.931013 2022] [wsgi:error] [pid 8604:tid 1872] [client 192.168.94.110:53080]     response = get_response(request)\r, referer: http://10.99.99.201:8012/fd
[Thu Oct 13 12:08:32.931013 2022] [wsgi:error] [pid 8604:tid 1872] [client 192.168.94.110:53080]   File "E:\\Python_project\\CharterIns\\venv\\Lib\\site-packages\\django\\core\\handlers\\base.py", line 197, in _get_response\r, referer: http://10.99.99.201:8012/fd
[Thu Oct 13 12:08:32.931013 2022] [wsgi:error] [pid 8604:tid 1872] [client 192.168.94.110:53080]     response = wrapped_callback(request, *callback_args, **callback_kwargs)\r, referer: http://10.99.99.201:8012/fd
[Thu Oct 13 12:08:32.931013 2022] [wsgi:error] [pid 8604:tid 1872] [client 192.168.94.110:53080]   File "E:\\Python_project\\A_Jalil_S_M-master\\PersonalInfo\\views.py", line 425, in landing\r, referer: http://10.99.99.201:8012/fd
[Thu Oct 13 12:08:32.931013 2022] [wsgi:error] [pid 8604:tid 1872] [client 192.168.94.110:53080]     return render(request,'landing.html')\r, referer: http://10.99.99.201:8012/fd
[Thu Oct 13 12:08:32.931013 2022] [wsgi:error] [pid 8604:tid 1872] [client 192.168.94.110:53080]   File "E:\\Python_project\\CharterIns\\venv\\Lib\\site-packages\\django\\shortcuts.py", line 24, in render\r, referer: http://10.99.99.201:8012/fd
[Thu Oct 13 12:08:32.931013 2022] [wsgi:error] [pid 8604:tid 1872] [client 192.168.94.110:53080]     content = loader.render_to_string(template_name, context, request, using=using)\r, referer: http://10.99.99.201:8012/fd
[Thu Oct 13 12:08:32.931013 2022] [wsgi:error] [pid 8604:tid 1872] [client 192.168.94.110:53080]   File "E:\\Python_project\\CharterIns\\venv\\Lib\\site-packages\\django\\template\\loader.py", line 62, in render_to_string\r, referer: http://10.99.99.201:8012/fd
[Thu Oct 13 12:08:32.931013 2022] [wsgi:error] [pid 8604:tid 1872] [client 192.168.94.110:53080]     return template.render(context, request)\r, referer: http://10.99.99.201:8012/fd
[Thu Oct 13 12:08:32.931013 2022] [wsgi:error] [pid 8604:tid 1872] [client 192.168.94.110:53080]   File "E:\\Python_project\\CharterIns\\venv\\Lib\\site-packages\\django\\template\\backends\\django.py", line 62, in render\r, referer: http://10.99.99.201:8012/fd
[Thu Oct 13 12:08:32.931013 2022] [wsgi:error] [pid 8604:tid 1872] [client 192.168.94.110:53080]     return self.template.render(context)\r, referer: http://10.99.99.201:8012/fd
[Thu Oct 13 12:08:32.931013 2022] [wsgi:error] [pid 8604:tid 1872] [client 192.168.94.110:53080]   File "E:\\Python_project\\CharterIns\\venv\\Lib\\site-packages\\django\\template\\base.py", line 175, in render\r, referer: http://10.99.99.201:8012/fd
[Thu Oct 13 12:08:32.931013 2022] [wsgi:error] [pid 8604:tid 1872] [client 192.168.94.110:53080]     return self._render(context)\r, referer: http://10.99.99.201:8012/fd
[Thu Oct 13 12:08:32.931013 2022] [wsgi:error] [pid 8604:tid 1872] [client 192.168.94.110:53080]   File "E:\\Python_project\\CharterIns\\venv\\Lib\\site-packages\\django\\template\\base.py", line 167, in _render\r, referer: http://10.99.99.201:8012/fd
[Thu Oct 13 12:08:32.931013 2022] [wsgi:error] [pid 8604:tid 1872] [client 192.168.94.110:53080]     return self.nodelist.render(context)\r, referer: http://10.99.99.201:8012/fd
[Thu Oct 13 12:08:32.931013 2022] [wsgi:error] [pid 8604:tid 1872] [client 192.168.94.110:53080]   File "E:\\Python_project\\CharterIns\\venv\\Lib\\site-packages\\django\\template\\base.py", line 1000, in render\r, referer: http://10.99.99.201:8012/fd
[Thu Oct 13 12:08:32.931013 2022] [wsgi:error] [pid 8604:tid 1872] [client 192.168.94.110:53080]     return SafeString("".join([node.render_annotated(context) for node in self]))\r, referer: http://10.99.99.201:8012/fd
[Thu Oct 13 12:08:32.931013 2022] [wsgi:error] [pid 8604:tid 1872] [client 192.168.94.110:53080]   File "E:\\Python_project\\CharterIns\\venv\\Lib\\site-packages\\django\\template\\base.py", line 1000, in <listcomp>\r, referer: http://10.99.99.201:8012/fd
[Thu Oct 13 12:08:32.931013 2022] [wsgi:error] [pid 8604:tid 1872] [client 192.168.94.110:53080]     return SafeString("".join([node.render_annotated(context) for node in self]))\r, referer: http://10.99.99.201:8012/fd
[Thu Oct 13 12:08:32.931013 2022] [wsgi:error] [pid 8604:tid 1872] [client 192.168.94.110:53080]   File "E:\\Python_project\\CharterIns\\venv\\Lib\\site-packages\\django\\template\\base.py", line 958, in render_annotated\r, referer: http://10.99.99.201:8012/fd
[Thu Oct 13 12:08:32.931013 2022] [wsgi:error] [pid 8604:tid 1872] [client 192.168.94.110:53080]     return self.render(context)\r, referer: http://10.99.99.201:8012/fd
[Thu Oct 13 12:08:32.931013 2022] [wsgi:error] [pid 8604:tid 1872] [client 192.168.94.110:53080]   File "E:\\Python_project\\CharterIns\\venv\\Lib\\site-packages\\django\\template\\loader_tags.py", line 157, in render\r, referer: http://10.99.99.201:8012/fd
[Thu Oct 13 12:08:32.931013 2022] [wsgi:error] [pid 8604:tid 1872] [client 192.168.94.110:53080]     return compiled_parent._render(context)\r, referer: http://10.99.99.201:8012/fd
[Thu Oct 13 12:08:32.931013 2022] [wsgi:error] [pid 8604:tid 1872] [client 192.168.94.110:53080]   File "E:\\Python_project\\CharterIns\\venv\\Lib\\site-packages\\django\\template\\base.py", line 167, in _render\r, referer: http://10.99.99.201:8012/fd
[Thu Oct 13 12:08:32.931013 2022] [wsgi:error] [pid 8604:tid 1872] [client 192.168.94.110:53080]     return self.nodelist.render(context)\r, referer: http://10.99.99.201:8012/fd
[Thu Oct 13 12:08:32.931013 2022] [wsgi:error] [pid 8604:tid 1872] [client 192.168.94.110:53080]   File "E:\\Python_project\\CharterIns\\venv\\Lib\\site-packages\\django\\template\\base.py", line 1000, in render\r, referer: http://10.99.99.201:8012/fd
[Thu Oct 13 12:08:32.931013 2022] [wsgi:error] [pid 8604:tid 1872] [client 192.168.94.110:53080]     return SafeString("".join([node.render_annotated(context) for node in self]))\r, referer: http://10.99.99.201:8012/fd
[Thu Oct 13 12:08:32.931013 2022] [wsgi:error] [pid 8604:tid 1872] [client 192.168.94.110:53080]   File "E:\\Python_project\\CharterIns\\venv\\Lib\\site-packages\\django\\template\\base.py", line 1000, in <listcomp>\r, referer: http://10.99.99.201:8012/fd
[Thu Oct 13 12:08:32.931013 2022] [wsgi:error] [pid 8604:tid 1872] [client 192.168.94.110:53080]     return SafeString("".join([node.render_annotated(context) for node in self]))\r, referer: http://10.99.99.201:8012/fd
[Thu Oct 13 12:08:32.931013 2022] [wsgi:error] [pid 8604:tid 1872] [client 192.168.94.110:53080]   File "E:\\Python_project\\CharterIns\\venv\\Lib\\site-packages\\django\\template\\base.py", line 958, in render_annotated\r, referer: http://10.99.99.201:8012/fd
[Thu Oct 13 12:08:32.931013 2022] [wsgi:error] [pid 8604:tid 1872] [client 192.168.94.110:53080]     return self.render(context)\r, referer: http://10.99.99.201:8012/fd
[Thu Oct 13 12:08:32.931013 2022] [wsgi:error] [pid 8604:tid 1872] [client 192.168.94.110:53080]   File "E:\\Python_project\\CharterIns\\venv\\Lib\\site-packages\\django\\template\\defaulttags.py", line 472, in render\r, referer: http://10.99.99.201:8012/fd
[Thu Oct 13 12:08:32.931013 2022] [wsgi:error] [pid 8604:tid 1872] [client 192.168.94.110:53080]     url = reverse(view_name, args=args, kwargs=kwargs, current_app=current_app)\r, referer: http://10.99.99.201:8012/fd
[Thu Oct 13 12:08:32.931013 2022] [wsgi:error] [pid 8604:tid 1872] [client 192.168.94.110:53080]   File "E:\\Python_project\\CharterIns\\venv\\Lib\\site-packages\\django\\urls\\base.py", line 88, in reverse\r, referer: http://10.99.99.201:8012/fd
[Thu Oct 13 12:08:32.931013 2022] [wsgi:error] [pid 8604:tid 1872] [client 192.168.94.110:53080]     return resolver._reverse_with_prefix(view, prefix, *args, **kwargs)\r, referer: http://10.99.99.201:8012/fd
[Thu Oct 13 12:08:32.931013 2022] [wsgi:error] [pid 8604:tid 1872] [client 192.168.94.110:53080]   File "E:\\Python_project\\CharterIns\\venv\\Lib\\site-packages\\django\\urls\\resolvers.py", line 802, in _reverse_with_prefix\r, referer: http://10.99.99.201:8012/fd
[Thu Oct 13 12:08:32.931013 2022] [wsgi:error] [pid 8604:tid 1872] [client 192.168.94.110:53080]     raise NoReverseMatch(msg)\r, referer: http://10.99.99.201:8012/fd
[Thu Oct 13 12:08:32.931013 2022] [wsgi:error] [pid 8604:tid 1872] [client 192.168.94.110:53080] django.urls.exceptions.NoReverseMatch: Reverse for 'files_upload' not found. 'files_upload' is not a valid view function or pattern name.\r, referer: http://10.99.99.201:8012/fd
[Thu Oct 13 12:09:39.338895 2022] [wsgi:error] [pid 5036:tid 1884] [client 192.168.101.70:52145] Internal Server Error: /fd/\r
[Thu Oct 13 12:09:39.338895 2022] [wsgi:error] [pid 5036:tid 1884] [client 192.168.101.70:52145] Traceback (most recent call last):\r
[Thu Oct 13 12:09:39.339894 2022] [wsgi:error] [pid 5036:tid 1884] [client 192.168.101.70:52145]   File "E:\\Python_project\\CharterIns\\venv\\Lib\\site-packages\\django\\core\\handlers\\exception.py", line 55, in inner\r
[Thu Oct 13 12:09:39.339894 2022] [wsgi:error] [pid 5036:tid 1884] [client 192.168.101.70:52145]     response = get_response(request)\r
[Thu Oct 13 12:09:39.339894 2022] [wsgi:error] [pid 5036:tid 1884] [client 192.168.101.70:52145]   File "E:\\Python_project\\CharterIns\\venv\\Lib\\site-packages\\django\\core\\handlers\\base.py", line 181, in _get_response\r
[Thu Oct 13 12:09:39.339894 2022] [wsgi:error] [pid 5036:tid 1884] [client 192.168.101.70:52145]     callback, callback_args, callback_kwargs = self.resolve_request(request)\r
[Thu Oct 13 12:09:39.339894 2022] [wsgi:error] [pid 5036:tid 1884] [client 192.168.101.70:52145]   File "E:\\Python_project\\CharterIns\\venv\\Lib\\site-packages\\django\\core\\handlers\\base.py", line 313, in resolve_request\r
[Thu Oct 13 12:09:39.339894 2022] [wsgi:error] [pid 5036:tid 1884] [client 192.168.101.70:52145]     resolver_match = resolver.resolve(request.path_info)\r
[Thu Oct 13 12:09:39.339894 2022] [wsgi:error] [pid 5036:tid 1884] [client 192.168.101.70:52145]   File "E:\\Python_project\\CharterIns\\venv\\Lib\\site-packages\\django\\urls\\resolvers.py", line 649, in resolve\r
[Thu Oct 13 12:09:39.339894 2022] [wsgi:error] [pid 5036:tid 1884] [client 192.168.101.70:52145]     for pattern in self.url_patterns:\r
[Thu Oct 13 12:09:39.339894 2022] [wsgi:error] [pid 5036:tid 1884] [client 192.168.101.70:52145]   File "E:\\Python_project\\CharterIns\\venv\\Lib\\site-packages\\django\\utils\\functional.py", line 49, in __get__\r
[Thu Oct 13 12:09:39.339894 2022] [wsgi:error] [pid 5036:tid 1884] [client 192.168.101.70:52145]     res = instance.__dict__[self.name] = self.func(instance)\r
[Thu Oct 13 12:09:39.339894 2022] [wsgi:error] [pid 5036:tid 1884] [client 192.168.101.70:52145]   File "E:\\Python_project\\CharterIns\\venv\\Lib\\site-packages\\django\\urls\\resolvers.py", line 696, in url_patterns\r
[Thu Oct 13 12:09:39.339894 2022] [wsgi:error] [pid 5036:tid 1884] [client 192.168.101.70:52145]     patterns = getattr(self.urlconf_module, "urlpatterns", self.urlconf_module)\r
[Thu Oct 13 12:09:39.339894 2022] [wsgi:error] [pid 5036:tid 1884] [client 192.168.101.70:52145]   File "E:\\Python_project\\CharterIns\\venv\\Lib\\site-packages\\django\\utils\\functional.py", line 49, in __get__\r
[Thu Oct 13 12:09:39.339894 2022] [wsgi:error] [pid 5036:tid 1884] [client 192.168.101.70:52145]     res = instance.__dict__[self.name] = self.func(instance)\r
[Thu Oct 13 12:09:39.339894 2022] [wsgi:error] [pid 5036:tid 1884] [client 192.168.101.70:52145]   File "E:\\Python_project\\CharterIns\\venv\\Lib\\site-packages\\django\\urls\\resolvers.py", line 689, in urlconf_module\r
[Thu Oct 13 12:09:39.339894 2022] [wsgi:error] [pid 5036:tid 1884] [client 192.168.101.70:52145]     return import_module(self.urlconf_name)\r
[Thu Oct 13 12:09:39.339894 2022] [wsgi:error] [pid 5036:tid 1884] [client 192.168.101.70:52145]   File "C:\\Users\\Administrator\\AppData\\Local\\Programs\\Python\\Python310\\Lib\\importlib\\__init__.py", line 126, in import_module\r
[Thu Oct 13 12:09:39.339894 2022] [wsgi:error] [pid 5036:tid 1884] [client 192.168.101.70:52145]     return _bootstrap._gcd_import(name[level:], package, level)\r
[Thu Oct 13 12:09:39.339894 2022] [wsgi:error] [pid 5036:tid 1884] [client 192.168.101.70:52145]   File "<frozen importlib._bootstrap>", line 1050, in _gcd_import\r
[Thu Oct 13 12:09:39.339894 2022] [wsgi:error] [pid 5036:tid 1884] [client 192.168.101.70:52145]   File "<frozen importlib._bootstrap>", line 1027, in _find_and_load\r
[Thu Oct 13 12:09:39.339894 2022] [wsgi:error] [pid 5036:tid 1884] [client 192.168.101.70:52145]   File "<frozen importlib._bootstrap>", line 1006, in _find_and_load_unlocked\r
[Thu Oct 13 12:09:39.339894 2022] [wsgi:error] [pid 5036:tid 1884] [client 192.168.101.70:52145]   File "<frozen importlib._bootstrap>", line 688, in _load_unlocked\r
[Thu Oct 13 12:09:39.339894 2022] [wsgi:error] [pid 5036:tid 1884] [client 192.168.101.70:52145]   File "<frozen importlib._bootstrap_external>", line 883, in exec_module\r
[Thu Oct 13 12:09:39.339894 2022] [wsgi:error] [pid 5036:tid 1884] [client 192.168.101.70:52145]   File "<frozen importlib._bootstrap>", line 241, in _call_with_frames_removed\r
[Thu Oct 13 12:09:39.339894 2022] [wsgi:error] [pid 5036:tid 1884] [client 192.168.101.70:52145]   File "E:\\Python_project\\A_Jalil_S_M-master\\A_Jalil_S_M\\urls.py", line 25, in <module>\r
[Thu Oct 13 12:09:39.339894 2022] [wsgi:error] [pid 5036:tid 1884] [client 192.168.101.70:52145]     path('',include('PersonalInfo.urls')),\r
[Thu Oct 13 12:09:39.339894 2022] [wsgi:error] [pid 5036:tid 1884] [client 192.168.101.70:52145]   File "E:\\Python_project\\CharterIns\\venv\\Lib\\site-packages\\django\\urls\\conf.py", line 38, in include\r
[Thu Oct 13 12:09:39.339894 2022] [wsgi:error] [pid 5036:tid 1884] [client 192.168.101.70:52145]     urlconf_module = import_module(urlconf_module)\r
[Thu Oct 13 12:09:39.339894 2022] [wsgi:error] [pid 5036:tid 1884] [client 192.168.101.70:52145]   File "C:\\Users\\Administrator\\AppData\\Local\\Programs\\Python\\Python310\\Lib\\importlib\\__init__.py", line 126, in import_module\r
[Thu Oct 13 12:09:39.339894 2022] [wsgi:error] [pid 5036:tid 1884] [client 192.168.101.70:52145]     return _bootstrap._gcd_import(name[level:], package, level)\r
[Thu Oct 13 12:09:39.339894 2022] [wsgi:error] [pid 5036:tid 1884] [client 192.168.101.70:52145]   File "<frozen importlib._bootstrap>", line 1050, in _gcd_import\r
[Thu Oct 13 12:09:39.339894 2022] [wsgi:error] [pid 5036:tid 1884] [client 192.168.101.70:52145]   File "<frozen importlib._bootstrap>", line 1027, in _find_and_load\r
[Thu Oct 13 12:09:39.339894 2022] [wsgi:error] [pid 5036:tid 1884] [client 192.168.101.70:52145]   File "<frozen importlib._bootstrap>", line 1006, in _find_and_load_unlocked\r
[Thu Oct 13 12:09:39.339894 2022] [wsgi:error] [pid 5036:tid 1884] [client 192.168.101.70:52145]   File "<frozen importlib._bootstrap>", line 688, in _load_unlocked\r
[Thu Oct 13 12:09:39.339894 2022] [wsgi:error] [pid 5036:tid 1884] [client 192.168.101.70:52145]   File "<frozen importlib._bootstrap_external>", line 883, in exec_module\r
[Thu Oct 13 12:09:39.339894 2022] [wsgi:error] [pid 5036:tid 1884] [client 192.168.101.70:52145]   File "<frozen importlib._bootstrap>", line 241, in _call_with_frames_removed\r
[Thu Oct 13 12:09:39.339894 2022] [wsgi:error] [pid 5036:tid 1884] [client 192.168.101.70:52145]   File "E:\\Python_project\\A_Jalil_S_M-master\\PersonalInfo\\urls.py", line 29, in <module>\r
[Thu Oct 13 12:09:39.339894 2022] [wsgi:error] [pid 5036:tid 1884] [client 192.168.101.70:52145]     path('utils', utils, name='utils'),\r
[Thu Oct 13 12:09:39.339894 2022] [wsgi:error] [pid 5036:tid 1884] [client 192.168.101.70:52145] NameError: name 'utils' is not defined\r
[Thu Oct 13 12:09:43.973095 2022] [wsgi:error] [pid 5036:tid 1884] [client 192.168.101.70:52148] Internal Server Error: /fd/\r
[Thu Oct 13 12:09:43.973095 2022] [wsgi:error] [pid 5036:tid 1884] [client 192.168.101.70:52148] Traceback (most recent call last):\r
[Thu Oct 13 12:09:43.973095 2022] [wsgi:error] [pid 5036:tid 1884] [client 192.168.101.70:52148]   File "E:\\Python_project\\CharterIns\\venv\\Lib\\site-packages\\django\\core\\handlers\\exception.py", line 55, in inner\r
[Thu Oct 13 12:09:43.973095 2022] [wsgi:error] [pid 5036:tid 1884] [client 192.168.101.70:52148]     response = get_response(request)\r
[Thu Oct 13 12:09:43.973095 2022] [wsgi:error] [pid 5036:tid 1884] [client 192.168.101.70:52148]   File "E:\\Python_project\\CharterIns\\venv\\Lib\\site-packages\\django\\core\\handlers\\base.py", line 181, in _get_response\r
[Thu Oct 13 12:09:43.973095 2022] [wsgi:error] [pid 5036:tid 1884] [client 192.168.101.70:52148]     callback, callback_args, callback_kwargs = self.resolve_request(request)\r
[Thu Oct 13 12:09:43.973095 2022] [wsgi:error] [pid 5036:tid 1884] [client 192.168.101.70:52148]   File "E:\\Python_project\\CharterIns\\venv\\Lib\\site-packages\\django\\core\\handlers\\base.py", line 313, in resolve_request\r
[Thu Oct 13 12:09:43.973095 2022] [wsgi:error] [pid 5036:tid 1884] [client 192.168.101.70:52148]     resolver_match = resolver.resolve(request.path_info)\r
[Thu Oct 13 12:09:43.973095 2022] [wsgi:error] [pid 5036:tid 1884] [client 192.168.101.70:52148]   File "E:\\Python_project\\CharterIns\\venv\\Lib\\site-packages\\django\\urls\\resolvers.py", line 649, in resolve\r
[Thu Oct 13 12:09:43.973095 2022] [wsgi:error] [pid 5036:tid 1884] [client 192.168.101.70:52148]     for pattern in self.url_patterns:\r
[Thu Oct 13 12:09:43.973095 2022] [wsgi:error] [pid 5036:tid 1884] [client 192.168.101.70:52148]   File "E:\\Python_project\\CharterIns\\venv\\Lib\\site-packages\\django\\utils\\functional.py", line 49, in __get__\r
[Thu Oct 13 12:09:43.973095 2022] [wsgi:error] [pid 5036:tid 1884] [client 192.168.101.70:52148]     res = instance.__dict__[self.name] = self.func(instance)\r
[Thu Oct 13 12:09:43.973095 2022] [wsgi:error] [pid 5036:tid 1884] [client 192.168.101.70:52148]   File "E:\\Python_project\\CharterIns\\venv\\Lib\\site-packages\\django\\urls\\resolvers.py", line 696, in url_patterns\r
[Thu Oct 13 12:09:43.973095 2022] [wsgi:error] [pid 5036:tid 1884] [client 192.168.101.70:52148]     patterns = getattr(self.urlconf_module, "urlpatterns", self.urlconf_module)\r
[Thu Oct 13 12:09:43.973095 2022] [wsgi:error] [pid 5036:tid 1884] [client 192.168.101.70:52148]   File "E:\\Python_project\\CharterIns\\venv\\Lib\\site-packages\\django\\utils\\functional.py", line 49, in __get__\r
[Thu Oct 13 12:09:43.973095 2022] [wsgi:error] [pid 5036:tid 1884] [client 192.168.101.70:52148]     res = instance.__dict__[self.name] = self.func(instance)\r
[Thu Oct 13 12:09:43.973095 2022] [wsgi:error] [pid 5036:tid 1884] [client 192.168.101.70:52148]   File "E:\\Python_project\\CharterIns\\venv\\Lib\\site-packages\\django\\urls\\resolvers.py", line 689, in urlconf_module\r
[Thu Oct 13 12:09:43.973095 2022] [wsgi:error] [pid 5036:tid 1884] [client 192.168.101.70:52148]     return import_module(self.urlconf_name)\r
[Thu Oct 13 12:09:43.973095 2022] [wsgi:error] [pid 5036:tid 1884] [client 192.168.101.70:52148]   File "C:\\Users\\Administrator\\AppData\\Local\\Programs\\Python\\Python310\\Lib\\importlib\\__init__.py", line 126, in import_module\r
[Thu Oct 13 12:09:43.973095 2022] [wsgi:error] [pid 5036:tid 1884] [client 192.168.101.70:52148]     return _bootstrap._gcd_import(name[level:], package, level)\r
[Thu Oct 13 12:09:43.973095 2022] [wsgi:error] [pid 5036:tid 1884] [client 192.168.101.70:52148]   File "<frozen importlib._bootstrap>", line 1050, in _gcd_import\r
[Thu Oct 13 12:09:43.973095 2022] [wsgi:error] [pid 5036:tid 1884] [client 192.168.101.70:52148]   File "<frozen importlib._bootstrap>", line 1027, in _find_and_load\r
[Thu Oct 13 12:09:43.973095 2022] [wsgi:error] [pid 5036:tid 1884] [client 192.168.101.70:52148]   File "<frozen importlib._bootstrap>", line 1006, in _find_and_load_unlocked\r
[Thu Oct 13 12:09:43.973095 2022] [wsgi:error] [pid 5036:tid 1884] [client 192.168.101.70:52148]   File "<frozen importlib._bootstrap>", line 688, in _load_unlocked\r
[Thu Oct 13 12:09:43.973095 2022] [wsgi:error] [pid 5036:tid 1884] [client 192.168.101.70:52148]   File "<frozen importlib._bootstrap_external>", line 883, in exec_module\r
[Thu Oct 13 12:09:43.973095 2022] [wsgi:error] [pid 5036:tid 1884] [client 192.168.101.70:52148]   File "<frozen importlib._bootstrap>", line 241, in _call_with_frames_removed\r
[Thu Oct 13 12:09:43.973095 2022] [wsgi:error] [pid 5036:tid 1884] [client 192.168.101.70:52148]   File "E:\\Python_project\\A_Jalil_S_M-master\\A_Jalil_S_M\\urls.py", line 25, in <module>\r
[Thu Oct 13 12:09:43.973095 2022] [wsgi:error] [pid 5036:tid 1884] [client 192.168.101.70:52148]     path('',include('PersonalInfo.urls')),\r
[Thu Oct 13 12:09:43.973095 2022] [wsgi:error] [pid 5036:tid 1884] [client 192.168.101.70:52148]   File "E:\\Python_project\\CharterIns\\venv\\Lib\\site-packages\\django\\urls\\conf.py", line 38, in include\r
[Thu Oct 13 12:09:43.973095 2022] [wsgi:error] [pid 5036:tid 1884] [client 192.168.101.70:52148]     urlconf_module = import_module(urlconf_module)\r
[Thu Oct 13 12:09:43.973095 2022] [wsgi:error] [pid 5036:tid 1884] [client 192.168.101.70:52148]   File "C:\\Users\\Administrator\\AppData\\Local\\Programs\\Python\\Python310\\Lib\\importlib\\__init__.py", line 126, in import_module\r
[Thu Oct 13 12:09:43.973095 2022] [wsgi:error] [pid 5036:tid 1884] [client 192.168.101.70:52148]     return _bootstrap._gcd_import(name[level:], package, level)\r
[Thu Oct 13 12:09:43.973095 2022] [wsgi:error] [pid 5036:tid 1884] [client 192.168.101.70:52148]   File "<frozen importlib._bootstrap>", line 1050, in _gcd_import\r
[Thu Oct 13 12:09:43.973095 2022] [wsgi:error] [pid 5036:tid 1884] [client 192.168.101.70:52148]   File "<frozen importlib._bootstrap>", line 1027, in _find_and_load\r
[Thu Oct 13 12:09:43.973095 2022] [wsgi:error] [pid 5036:tid 1884] [client 192.168.101.70:52148]   File "<frozen importlib._bootstrap>", line 1006, in _find_and_load_unlocked\r
[Thu Oct 13 12:09:43.973095 2022] [wsgi:error] [pid 5036:tid 1884] [client 192.168.101.70:52148]   File "<frozen importlib._bootstrap>", line 688, in _load_unlocked\r
[Thu Oct 13 12:09:43.973095 2022] [wsgi:error] [pid 5036:tid 1884] [client 192.168.101.70:52148]   File "<frozen importlib._bootstrap_external>", line 883, in exec_module\r
[Thu Oct 13 12:09:43.973095 2022] [wsgi:error] [pid 5036:tid 1884] [client 192.168.101.70:52148]   File "<frozen importlib._bootstrap>", line 241, in _call_with_frames_removed\r
[Thu Oct 13 12:09:43.973095 2022] [wsgi:error] [pid 5036:tid 1884] [client 192.168.101.70:52148]   File "E:\\Python_project\\A_Jalil_S_M-master\\PersonalInfo\\urls.py", line 29, in <module>\r
[Thu Oct 13 12:09:43.973095 2022] [wsgi:error] [pid 5036:tid 1884] [client 192.168.101.70:52148]     path('utils', utils, name='utils'),\r
[Thu Oct 13 12:09:43.973095 2022] [wsgi:error] [pid 5036:tid 1884] [client 192.168.101.70:52148] NameError: name 'utils' is not defined\r
[Thu Oct 13 12:09:47.245462 2022] [wsgi:error] [pid 5036:tid 1884] [client 192.168.101.70:52151] Internal Server Error: /fd/\r
[Thu Oct 13 12:09:47.245462 2022] [wsgi:error] [pid 5036:tid 1884] [client 192.168.101.70:52151] Traceback (most recent call last):\r
[Thu Oct 13 12:09:47.245462 2022] [wsgi:error] [pid 5036:tid 1884] [client 192.168.101.70:52151]   File "E:\\Python_project\\CharterIns\\venv\\Lib\\site-packages\\django\\core\\handlers\\exception.py", line 55, in inner\r
[Thu Oct 13 12:09:47.245462 2022] [wsgi:error] [pid 5036:tid 1884] [client 192.168.101.70:52151]     response = get_response(request)\r
[Thu Oct 13 12:09:47.245462 2022] [wsgi:error] [pid 5036:tid 1884] [client 192.168.101.70:52151]   File "E:\\Python_project\\CharterIns\\venv\\Lib\\site-packages\\django\\core\\handlers\\base.py", line 181, in _get_response\r
[Thu Oct 13 12:09:47.245462 2022] [wsgi:error] [pid 5036:tid 1884] [client 192.168.101.70:52151]     callback, callback_args, callback_kwargs = self.resolve_request(request)\r
[Thu Oct 13 12:09:47.245462 2022] [wsgi:error] [pid 5036:tid 1884] [client 192.168.101.70:52151]   File "E:\\Python_project\\CharterIns\\venv\\Lib\\site-packages\\django\\core\\handlers\\base.py", line 313, in resolve_request\r
[Thu Oct 13 12:09:47.245462 2022] [wsgi:error] [pid 5036:tid 1884] [client 192.168.101.70:52151]     resolver_match = resolver.resolve(request.path_info)\r
[Thu Oct 13 12:09:47.246463 2022] [wsgi:error] [pid 5036:tid 1884] [client 192.168.101.70:52151]   File "E:\\Python_project\\CharterIns\\venv\\Lib\\site-packages\\django\\urls\\resolvers.py", line 649, in resolve\r
[Thu Oct 13 12:09:47.246463 2022] [wsgi:error] [pid 5036:tid 1884] [client 192.168.101.70:52151]     for pattern in self.url_patterns:\r
[Thu Oct 13 12:09:47.246463 2022] [wsgi:error] [pid 5036:tid 1884] [client 192.168.101.70:52151]   File "E:\\Python_project\\CharterIns\\venv\\Lib\\site-packages\\django\\utils\\functional.py", line 49, in __get__\r
[Thu Oct 13 12:09:47.246463 2022] [wsgi:error] [pid 5036:tid 1884] [client 192.168.101.70:52151]     res = instance.__dict__[self.name] = self.func(instance)\r
[Thu Oct 13 12:09:47.246463 2022] [wsgi:error] [pid 5036:tid 1884] [client 192.168.101.70:52151]   File "E:\\Python_project\\CharterIns\\venv\\Lib\\site-packages\\django\\urls\\resolvers.py", line 696, in url_patterns\r
[Thu Oct 13 12:09:47.246463 2022] [wsgi:error] [pid 5036:tid 1884] [client 192.168.101.70:52151]     patterns = getattr(self.urlconf_module, "urlpatterns", self.urlconf_module)\r
[Thu Oct 13 12:09:47.246463 2022] [wsgi:error] [pid 5036:tid 1884] [client 192.168.101.70:52151]   File "E:\\Python_project\\CharterIns\\venv\\Lib\\site-packages\\django\\utils\\functional.py", line 49, in __get__\r
[Thu Oct 13 12:09:47.246463 2022] [wsgi:error] [pid 5036:tid 1884] [client 192.168.101.70:52151]     res = instance.__dict__[self.name] = self.func(instance)\r
[Thu Oct 13 12:09:47.246463 2022] [wsgi:error] [pid 5036:tid 1884] [client 192.168.101.70:52151]   File "E:\\Python_project\\CharterIns\\venv\\Lib\\site-packages\\django\\urls\\resolvers.py", line 689, in urlconf_module\r
[Thu Oct 13 12:09:47.246463 2022] [wsgi:error] [pid 5036:tid 1884] [client 192.168.101.70:52151]     return import_module(self.urlconf_name)\r
[Thu Oct 13 12:09:47.246463 2022] [wsgi:error] [pid 5036:tid 1884] [client 192.168.101.70:52151]   File "C:\\Users\\Administrator\\AppData\\Local\\Programs\\Python\\Python310\\Lib\\importlib\\__init__.py", line 126, in import_module\r
[Thu Oct 13 12:09:47.246463 2022] [wsgi:error] [pid 5036:tid 1884] [client 192.168.101.70:52151]     return _bootstrap._gcd_import(name[level:], package, level)\r
[Thu Oct 13 12:09:47.246463 2022] [wsgi:error] [pid 5036:tid 1884] [client 192.168.101.70:52151]   File "<frozen importlib._bootstrap>", line 1050, in _gcd_import\r
[Thu Oct 13 12:09:47.246463 2022] [wsgi:error] [pid 5036:tid 1884] [client 192.168.101.70:52151]   File "<frozen importlib._bootstrap>", line 1027, in _find_and_load\r
[Thu Oct 13 12:09:47.246463 2022] [wsgi:error] [pid 5036:tid 1884] [client 192.168.101.70:52151]   File "<frozen importlib._bootstrap>", line 1006, in _find_and_load_unlocked\r
[Thu Oct 13 12:09:47.246463 2022] [wsgi:error] [pid 5036:tid 1884] [client 192.168.101.70:52151]   File "<frozen importlib._bootstrap>", line 688, in _load_unlocked\r
[Thu Oct 13 12:09:47.246463 2022] [wsgi:error] [pid 5036:tid 1884] [client 192.168.101.70:52151]   File "<frozen importlib._bootstrap_external>", line 883, in exec_module\r
[Thu Oct 13 12:09:47.246463 2022] [wsgi:error] [pid 5036:tid 1884] [client 192.168.101.70:52151]   File "<frozen importlib._bootstrap>", line 241, in _call_with_frames_removed\r
[Thu Oct 13 12:09:47.246463 2022] [wsgi:error] [pid 5036:tid 1884] [client 192.168.101.70:52151]   File "E:\\Python_project\\A_Jalil_S_M-master\\A_Jalil_S_M\\urls.py", line 25, in <module>\r
[Thu Oct 13 12:09:47.246463 2022] [wsgi:error] [pid 5036:tid 1884] [client 192.168.101.70:52151]     path('',include('PersonalInfo.urls')),\r
[Thu Oct 13 12:09:47.246463 2022] [wsgi:error] [pid 5036:tid 1884] [client 192.168.101.70:52151]   File "E:\\Python_project\\CharterIns\\venv\\Lib\\site-packages\\django\\urls\\conf.py", line 38, in include\r
[Thu Oct 13 12:09:47.246463 2022] [wsgi:error] [pid 5036:tid 1884] [client 192.168.101.70:52151]     urlconf_module = import_module(urlconf_module)\r
[Thu Oct 13 12:09:47.246463 2022] [wsgi:error] [pid 5036:tid 1884] [client 192.168.101.70:52151]   File "C:\\Users\\Administrator\\AppData\\Local\\Programs\\Python\\Python310\\Lib\\importlib\\__init__.py", line 126, in import_module\r
[Thu Oct 13 12:09:47.246463 2022] [wsgi:error] [pid 5036:tid 1884] [client 192.168.101.70:52151]     return _bootstrap._gcd_import(name[level:], package, level)\r
[Thu Oct 13 12:09:47.246463 2022] [wsgi:error] [pid 5036:tid 1884] [client 192.168.101.70:52151]   File "<frozen importlib._bootstrap>", line 1050, in _gcd_import\r
[Thu Oct 13 12:09:47.246463 2022] [wsgi:error] [pid 5036:tid 1884] [client 192.168.101.70:52151]   File "<frozen importlib._bootstrap>", line 1027, in _find_and_load\r
[Thu Oct 13 12:09:47.246463 2022] [wsgi:error] [pid 5036:tid 1884] [client 192.168.101.70:52151]   File "<frozen importlib._bootstrap>", line 1006, in _find_and_load_unlocked\r
[Thu Oct 13 12:09:47.246463 2022] [wsgi:error] [pid 5036:tid 1884] [client 192.168.101.70:52151]   File "<frozen importlib._bootstrap>", line 688, in _load_unlocked\r
[Thu Oct 13 12:09:47.246463 2022] [wsgi:error] [pid 5036:tid 1884] [client 192.168.101.70:52151]   File "<frozen importlib._bootstrap_external>", line 883, in exec_module\r
[Thu Oct 13 12:09:47.246463 2022] [wsgi:error] [pid 5036:tid 1884] [client 192.168.101.70:52151]   File "<frozen importlib._bootstrap>", line 241, in _call_with_frames_removed\r
[Thu Oct 13 12:09:47.246463 2022] [wsgi:error] [pid 5036:tid 1884] [client 192.168.101.70:52151]   File "E:\\Python_project\\A_Jalil_S_M-master\\PersonalInfo\\urls.py", line 29, in <module>\r
[Thu Oct 13 12:09:47.246463 2022] [wsgi:error] [pid 5036:tid 1884] [client 192.168.101.70:52151]     path('utils', utils, name='utils'),\r
[Thu Oct 13 12:09:47.246463 2022] [wsgi:error] [pid 5036:tid 1884] [client 192.168.101.70:52151] NameError: name 'utils' is not defined\r
[Thu Oct 13 12:09:51.416201 2022] [wsgi:error] [pid 5036:tid 1880] [client 192.168.94.110:53266] Internal Server Error: /fd/landing\r, referer: http://10.99.99.201:8012/fd
[Thu Oct 13 12:09:51.416201 2022] [wsgi:error] [pid 5036:tid 1880] [client 192.168.94.110:53266] Traceback (most recent call last):\r, referer: http://10.99.99.201:8012/fd
[Thu Oct 13 12:09:51.416201 2022] [wsgi:error] [pid 5036:tid 1880] [client 192.168.94.110:53266]   File "E:\\Python_project\\CharterIns\\venv\\Lib\\site-packages\\django\\core\\handlers\\exception.py", line 55, in inner\r, referer: http://10.99.99.201:8012/fd
[Thu Oct 13 12:09:51.416201 2022] [wsgi:error] [pid 5036:tid 1880] [client 192.168.94.110:53266]     response = get_response(request)\r, referer: http://10.99.99.201:8012/fd
[Thu Oct 13 12:09:51.416201 2022] [wsgi:error] [pid 5036:tid 1880] [client 192.168.94.110:53266]   File "E:\\Python_project\\CharterIns\\venv\\Lib\\site-packages\\django\\utils\\deprecation.py", line 133, in __call__\r, referer: http://10.99.99.201:8012/fd
[Thu Oct 13 12:09:51.416201 2022] [wsgi:error] [pid 5036:tid 1880] [client 192.168.94.110:53266]     response = self.process_request(request)\r, referer: http://10.99.99.201:8012/fd
[Thu Oct 13 12:09:51.416201 2022] [wsgi:error] [pid 5036:tid 1880] [client 192.168.94.110:53266]   File "E:\\Python_project\\CharterIns\\venv\\Lib\\site-packages\\django\\middleware\\common.py", line 53, in process_request\r, referer: http://10.99.99.201:8012/fd
[Thu Oct 13 12:09:51.416201 2022] [wsgi:error] [pid 5036:tid 1880] [client 192.168.94.110:53266]     if self.should_redirect_with_slash(request):\r, referer: http://10.99.99.201:8012/fd
[Thu Oct 13 12:09:51.416201 2022] [wsgi:error] [pid 5036:tid 1880] [client 192.168.94.110:53266]   File "E:\\Python_project\\CharterIns\\venv\\Lib\\site-packages\\django\\middleware\\common.py", line 70, in should_redirect_with_slash\r, referer: http://10.99.99.201:8012/fd
[Thu Oct 13 12:09:51.416201 2022] [wsgi:error] [pid 5036:tid 1880] [client 192.168.94.110:53266]     if not is_valid_path(request.path_info, urlconf):\r, referer: http://10.99.99.201:8012/fd
[Thu Oct 13 12:09:51.416201 2022] [wsgi:error] [pid 5036:tid 1880] [client 192.168.94.110:53266]   File "E:\\Python_project\\CharterIns\\venv\\Lib\\site-packages\\django\\urls\\base.py", line 155, in is_valid_path\r, referer: http://10.99.99.201:8012/fd
[Thu Oct 13 12:09:51.416201 2022] [wsgi:error] [pid 5036:tid 1880] [client 192.168.94.110:53266]     return resolve(path, urlconf)\r, referer: http://10.99.99.201:8012/fd
[Thu Oct 13 12:09:51.416201 2022] [wsgi:error] [pid 5036:tid 1880] [client 192.168.94.110:53266]   File "E:\\Python_project\\CharterIns\\venv\\Lib\\site-packages\\django\\urls\\base.py", line 24, in resolve\r, referer: http://10.99.99.201:8012/fd
[Thu Oct 13 12:09:51.416201 2022] [wsgi:error] [pid 5036:tid 1880] [client 192.168.94.110:53266]     return get_resolver(urlconf).resolve(path)\r, referer: http://10.99.99.201:8012/fd
[Thu Oct 13 12:09:51.416201 2022] [wsgi:error] [pid 5036:tid 1880] [client 192.168.94.110:53266]   File "E:\\Python_project\\CharterIns\\venv\\Lib\\site-packages\\django\\urls\\resolvers.py", line 649, in resolve\r, referer: http://10.99.99.201:8012/fd
[Thu Oct 13 12:09:51.416201 2022] [wsgi:error] [pid 5036:tid 1880] [client 192.168.94.110:53266]     for pattern in self.url_patterns:\r, referer: http://10.99.99.201:8012/fd
[Thu Oct 13 12:09:51.417200 2022] [wsgi:error] [pid 5036:tid 1880] [client 192.168.94.110:53266]   File "E:\\Python_project\\CharterIns\\venv\\Lib\\site-packages\\django\\utils\\functional.py", line 49, in __get__\r, referer: http://10.99.99.201:8012/fd
[Thu Oct 13 12:09:51.417200 2022] [wsgi:error] [pid 5036:tid 1880] [client 192.168.94.110:53266]     res = instance.__dict__[self.name] = self.func(instance)\r, referer: http://10.99.99.201:8012/fd
[Thu Oct 13 12:09:51.417200 2022] [wsgi:error] [pid 5036:tid 1880] [client 192.168.94.110:53266]   File "E:\\Python_project\\CharterIns\\venv\\Lib\\site-packages\\django\\urls\\resolvers.py", line 696, in url_patterns\r, referer: http://10.99.99.201:8012/fd
[Thu Oct 13 12:09:51.417200 2022] [wsgi:error] [pid 5036:tid 1880] [client 192.168.94.110:53266]     patterns = getattr(self.urlconf_module, "urlpatterns", self.urlconf_module)\r, referer: http://10.99.99.201:8012/fd
[Thu Oct 13 12:09:51.417200 2022] [wsgi:error] [pid 5036:tid 1880] [client 192.168.94.110:53266]   File "E:\\Python_project\\CharterIns\\venv\\Lib\\site-packages\\django\\utils\\functional.py", line 49, in __get__\r, referer: http://10.99.99.201:8012/fd
[Thu Oct 13 12:09:51.417200 2022] [wsgi:error] [pid 5036:tid 1880] [client 192.168.94.110:53266]     res = instance.__dict__[self.name] = self.func(instance)\r, referer: http://10.99.99.201:8012/fd
[Thu Oct 13 12:09:51.417200 2022] [wsgi:error] [pid 5036:tid 1880] [client 192.168.94.110:53266]   File "E:\\Python_project\\CharterIns\\venv\\Lib\\site-packages\\django\\urls\\resolvers.py", line 689, in urlconf_module\r, referer: http://10.99.99.201:8012/fd
[Thu Oct 13 12:09:51.417200 2022] [wsgi:error] [pid 5036:tid 1880] [client 192.168.94.110:53266]     return import_module(self.urlconf_name)\r, referer: http://10.99.99.201:8012/fd
[Thu Oct 13 12:09:51.417200 2022] [wsgi:error] [pid 5036:tid 1880] [client 192.168.94.110:53266]   File "C:\\Users\\Administrator\\AppData\\Local\\Programs\\Python\\Python310\\Lib\\importlib\\__init__.py", line 126, in import_module\r, referer: http://10.99.99.201:8012/fd
[Thu Oct 13 12:09:51.417200 2022] [wsgi:error] [pid 5036:tid 1880] [client 192.168.94.110:53266]     return _bootstrap._gcd_import(name[level:], package, level)\r, referer: http://10.99.99.201:8012/fd
[Thu Oct 13 12:09:51.417200 2022] [wsgi:error] [pid 5036:tid 1880] [client 192.168.94.110:53266]   File "<frozen importlib._bootstrap>", line 1050, in _gcd_import\r, referer: http://10.99.99.201:8012/fd
[Thu Oct 13 12:09:51.417200 2022] [wsgi:error] [pid 5036:tid 1880] [client 192.168.94.110:53266]   File "<frozen importlib._bootstrap>", line 1027, in _find_and_load\r, referer: http://10.99.99.201:8012/fd
[Thu Oct 13 12:09:51.417200 2022] [wsgi:error] [pid 5036:tid 1880] [client 192.168.94.110:53266]   File "<frozen importlib._bootstrap>", line 1006, in _find_and_load_unlocked\r, referer: http://10.99.99.201:8012/fd
[Thu Oct 13 12:09:51.417200 2022] [wsgi:error] [pid 5036:tid 1880] [client 192.168.94.110:53266]   File "<frozen importlib._bootstrap>", line 688, in _load_unlocked\r, referer: http://10.99.99.201:8012/fd
[Thu Oct 13 12:09:51.417200 2022] [wsgi:error] [pid 5036:tid 1880] [client 192.168.94.110:53266]   File "<frozen importlib._bootstrap_external>", line 883, in exec_module\r, referer: http://10.99.99.201:8012/fd
[Thu Oct 13 12:09:51.417200 2022] [wsgi:error] [pid 5036:tid 1880] [client 192.168.94.110:53266]   File "<frozen importlib._bootstrap>", line 241, in _call_with_frames_removed\r, referer: http://10.99.99.201:8012/fd
[Thu Oct 13 12:09:51.417200 2022] [wsgi:error] [pid 5036:tid 1880] [client 192.168.94.110:53266]   File "E:\\Python_project\\A_Jalil_S_M-master\\A_Jalil_S_M\\urls.py", line 25, in <module>\r, referer: http://10.99.99.201:8012/fd
[Thu Oct 13 12:09:51.417200 2022] [wsgi:error] [pid 5036:tid 1880] [client 192.168.94.110:53266]     path('',include('PersonalInfo.urls')),\r, referer: http://10.99.99.201:8012/fd
[Thu Oct 13 12:09:51.417200 2022] [wsgi:error] [pid 5036:tid 1880] [client 192.168.94.110:53266]   File "E:\\Python_project\\CharterIns\\venv\\Lib\\site-packages\\django\\urls\\conf.py", line 38, in include\r, referer: http://10.99.99.201:8012/fd
[Thu Oct 13 12:09:51.417200 2022] [wsgi:error] [pid 5036:tid 1880] [client 192.168.94.110:53266]     urlconf_module = import_module(urlconf_module)\r, referer: http://10.99.99.201:8012/fd
[Thu Oct 13 12:09:51.417200 2022] [wsgi:error] [pid 5036:tid 1880] [client 192.168.94.110:53266]   File "C:\\Users\\Administrator\\AppData\\Local\\Programs\\Python\\Python310\\Lib\\importlib\\__init__.py", line 126, in import_module\r, referer: http://10.99.99.201:8012/fd
[Thu Oct 13 12:09:51.417200 2022] [wsgi:error] [pid 5036:tid 1880] [client 192.168.94.110:53266]     return _bootstrap._gcd_import(name[level:], package, level)\r, referer: http://10.99.99.201:8012/fd
[Thu Oct 13 12:09:51.417200 2022] [wsgi:error] [pid 5036:tid 1880] [client 192.168.94.110:53266]   File "<frozen importlib._bootstrap>", line 1050, in _gcd_import\r, referer: http://10.99.99.201:8012/fd
[Thu Oct 13 12:09:51.417200 2022] [wsgi:error] [pid 5036:tid 1880] [client 192.168.94.110:53266]   File "<frozen importlib._bootstrap>", line 1027, in _find_and_load\r, referer: http://10.99.99.201:8012/fd
[Thu Oct 13 12:09:51.417200 2022] [wsgi:error] [pid 5036:tid 1880] [client 192.168.94.110:53266]   File "<frozen importlib._bootstrap>", line 1006, in _find_and_load_unlocked\r, referer: http://10.99.99.201:8012/fd
[Thu Oct 13 12:09:51.417200 2022] [wsgi:error] [pid 5036:tid 1880] [client 192.168.94.110:53266]   File "<frozen importlib._bootstrap>", line 688, in _load_unlocked\r, referer: http://10.99.99.201:8012/fd
[Thu Oct 13 12:09:51.417200 2022] [wsgi:error] [pid 5036:tid 1880] [client 192.168.94.110:53266]   File "<frozen importlib._bootstrap_external>", line 883, in exec_module\r, referer: http://10.99.99.201:8012/fd
[Thu Oct 13 12:09:51.417200 2022] [wsgi:error] [pid 5036:tid 1880] [client 192.168.94.110:53266]   File "<frozen importlib._bootstrap>", line 241, in _call_with_frames_removed\r, referer: http://10.99.99.201:8012/fd
[Thu Oct 13 12:09:51.417200 2022] [wsgi:error] [pid 5036:tid 1880] [client 192.168.94.110:53266]   File "E:\\Python_project\\A_Jalil_S_M-master\\PersonalInfo\\urls.py", line 29, in <module>\r, referer: http://10.99.99.201:8012/fd
[Thu Oct 13 12:09:51.417200 2022] [wsgi:error] [pid 5036:tid 1880] [client 192.168.94.110:53266]     path('utils', utils, name='utils'),\r, referer: http://10.99.99.201:8012/fd
[Thu Oct 13 12:09:51.417200 2022] [wsgi:error] [pid 5036:tid 1880] [client 192.168.94.110:53266] NameError: name 'utils' is not defined\r, referer: http://10.99.99.201:8012/fd
[Thu Oct 13 12:09:52.157010 2022] [wsgi:error] [pid 5036:tid 1880] [client 192.168.101.70:52153] Internal Server Error: /fd/\r
[Thu Oct 13 12:09:52.157010 2022] [wsgi:error] [pid 5036:tid 1880] [client 192.168.101.70:52153] Traceback (most recent call last):\r
[Thu Oct 13 12:09:52.158009 2022] [wsgi:error] [pid 5036:tid 1880] [client 192.168.101.70:52153]   File "E:\\Python_project\\CharterIns\\venv\\Lib\\site-packages\\django\\core\\handlers\\exception.py", line 55, in inner\r
[Thu Oct 13 12:09:52.158009 2022] [wsgi:error] [pid 5036:tid 1880] [client 192.168.101.70:52153]     response = get_response(request)\r
[Thu Oct 13 12:09:52.158009 2022] [wsgi:error] [pid 5036:tid 1880] [client 192.168.101.70:52153]   File "E:\\Python_project\\CharterIns\\venv\\Lib\\site-packages\\django\\core\\handlers\\base.py", line 181, in _get_response\r
[Thu Oct 13 12:09:52.158009 2022] [wsgi:error] [pid 5036:tid 1880] [client 192.168.101.70:52153]     callback, callback_args, callback_kwargs = self.resolve_request(request)\r
[Thu Oct 13 12:09:52.158009 2022] [wsgi:error] [pid 5036:tid 1880] [client 192.168.101.70:52153]   File "E:\\Python_project\\CharterIns\\venv\\Lib\\site-packages\\django\\core\\handlers\\base.py", line 313, in resolve_request\r
[Thu Oct 13 12:09:52.158009 2022] [wsgi:error] [pid 5036:tid 1880] [client 192.168.101.70:52153]     resolver_match = resolver.resolve(request.path_info)\r
[Thu Oct 13 12:09:52.158009 2022] [wsgi:error] [pid 5036:tid 1880] [client 192.168.101.70:52153]   File "E:\\Python_project\\CharterIns\\venv\\Lib\\site-packages\\django\\urls\\resolvers.py", line 649, in resolve\r
[Thu Oct 13 12:09:52.158009 2022] [wsgi:error] [pid 5036:tid 1880] [client 192.168.101.70:52153]     for pattern in self.url_patterns:\r
[Thu Oct 13 12:09:52.158009 2022] [wsgi:error] [pid 5036:tid 1880] [client 192.168.101.70:52153]   File "E:\\Python_project\\CharterIns\\venv\\Lib\\site-packages\\django\\utils\\functional.py", line 49, in __get__\r
[Thu Oct 13 12:09:52.158009 2022] [wsgi:error] [pid 5036:tid 1880] [client 192.168.101.70:52153]     res = instance.__dict__[self.name] = self.func(instance)\r
[Thu Oct 13 12:09:52.158009 2022] [wsgi:error] [pid 5036:tid 1880] [client 192.168.101.70:52153]   File "E:\\Python_project\\CharterIns\\venv\\Lib\\site-packages\\django\\urls\\resolvers.py", line 696, in url_patterns\r
[Thu Oct 13 12:09:52.158009 2022] [wsgi:error] [pid 5036:tid 1880] [client 192.168.101.70:52153]     patterns = getattr(self.urlconf_module, "urlpatterns", self.urlconf_module)\r
[Thu Oct 13 12:09:52.158009 2022] [wsgi:error] [pid 5036:tid 1880] [client 192.168.101.70:52153]   File "E:\\Python_project\\CharterIns\\venv\\Lib\\site-packages\\django\\utils\\functional.py", line 49, in __get__\r
[Thu Oct 13 12:09:52.158009 2022] [wsgi:error] [pid 5036:tid 1880] [client 192.168.101.70:52153]     res = instance.__dict__[self.name] = self.func(instance)\r
[Thu Oct 13 12:09:52.158009 2022] [wsgi:error] [pid 5036:tid 1880] [client 192.168.101.70:52153]   File "E:\\Python_project\\CharterIns\\venv\\Lib\\site-packages\\django\\urls\\resolvers.py", line 689, in urlconf_module\r
[Thu Oct 13 12:09:52.158009 2022] [wsgi:error] [pid 5036:tid 1880] [client 192.168.101.70:52153]     return import_module(self.urlconf_name)\r
[Thu Oct 13 12:09:52.158009 2022] [wsgi:error] [pid 5036:tid 1880] [client 192.168.101.70:52153]   File "C:\\Users\\Administrator\\AppData\\Local\\Programs\\Python\\Python310\\Lib\\importlib\\__init__.py", line 126, in import_module\r
[Thu Oct 13 12:09:52.158009 2022] [wsgi:error] [pid 5036:tid 1880] [client 192.168.101.70:52153]     return _bootstrap._gcd_import(name[level:], package, level)\r
[Thu Oct 13 12:09:52.158009 2022] [wsgi:error] [pid 5036:tid 1880] [client 192.168.101.70:52153]   File "<frozen importlib._bootstrap>", line 1050, in _gcd_import\r
[Thu Oct 13 12:09:52.158009 2022] [wsgi:error] [pid 5036:tid 1880] [client 192.168.101.70:52153]   File "<frozen importlib._bootstrap>", line 1027, in _find_and_load\r
[Thu Oct 13 12:09:52.158009 2022] [wsgi:error] [pid 5036:tid 1880] [client 192.168.101.70:52153]   File "<frozen importlib._bootstrap>", line 1006, in _find_and_load_unlocked\r
[Thu Oct 13 12:09:52.159007 2022] [wsgi:error] [pid 5036:tid 1880] [client 192.168.101.70:52153]   File "<frozen importlib._bootstrap>", line 688, in _load_unlocked\r
[Thu Oct 13 12:09:52.159007 2022] [wsgi:error] [pid 5036:tid 1880] [client 192.168.101.70:52153]   File "<frozen importlib._bootstrap_external>", line 883, in exec_module\r
[Thu Oct 13 12:09:52.159007 2022] [wsgi:error] [pid 5036:tid 1880] [client 192.168.101.70:52153]   File "<frozen importlib._bootstrap>", line 241, in _call_with_frames_removed\r
[Thu Oct 13 12:09:52.159007 2022] [wsgi:error] [pid 5036:tid 1880] [client 192.168.101.70:52153]   File "E:\\Python_project\\A_Jalil_S_M-master\\A_Jalil_S_M\\urls.py", line 25, in <module>\r
[Thu Oct 13 12:09:52.159007 2022] [wsgi:error] [pid 5036:tid 1880] [client 192.168.101.70:52153]     path('',include('PersonalInfo.urls')),\r
[Thu Oct 13 12:09:52.159007 2022] [wsgi:error] [pid 5036:tid 1880] [client 192.168.101.70:52153]   File "E:\\Python_project\\CharterIns\\venv\\Lib\\site-packages\\django\\urls\\conf.py", line 38, in include\r
[Thu Oct 13 12:09:52.159007 2022] [wsgi:error] [pid 5036:tid 1880] [client 192.168.101.70:52153]     urlconf_module = import_module(urlconf_module)\r
[Thu Oct 13 12:09:52.159007 2022] [wsgi:error] [pid 5036:tid 1880] [client 192.168.101.70:52153]   File "C:\\Users\\Administrator\\AppData\\Local\\Programs\\Python\\Python310\\Lib\\importlib\\__init__.py", line 126, in import_module\r
[Thu Oct 13 12:09:52.159007 2022] [wsgi:error] [pid 5036:tid 1880] [client 192.168.101.70:52153]     return _bootstrap._gcd_import(name[level:], package, level)\r
[Thu Oct 13 12:09:52.159007 2022] [wsgi:error] [pid 5036:tid 1880] [client 192.168.101.70:52153]   File "<frozen importlib._bootstrap>", line 1050, in _gcd_import\r
[Thu Oct 13 12:09:52.159007 2022] [wsgi:error] [pid 5036:tid 1880] [client 192.168.101.70:52153]   File "<frozen importlib._bootstrap>", line 1027, in _find_and_load\r
[Thu Oct 13 12:09:52.159007 2022] [wsgi:error] [pid 5036:tid 1880] [client 192.168.101.70:52153]   File "<frozen importlib._bootstrap>", line 1006, in _find_and_load_unlocked\r
[Thu Oct 13 12:09:52.159007 2022] [wsgi:error] [pid 5036:tid 1880] [client 192.168.101.70:52153]   File "<frozen importlib._bootstrap>", line 688, in _load_unlocked\r
[Thu Oct 13 12:09:52.159007 2022] [wsgi:error] [pid 5036:tid 1880] [client 192.168.101.70:52153]   File "<frozen importlib._bootstrap_external>", line 883, in exec_module\r
[Thu Oct 13 12:09:52.159007 2022] [wsgi:error] [pid 5036:tid 1880] [client 192.168.101.70:52153]   File "<frozen importlib._bootstrap>", line 241, in _call_with_frames_removed\r
[Thu Oct 13 12:09:52.159007 2022] [wsgi:error] [pid 5036:tid 1880] [client 192.168.101.70:52153]   File "E:\\Python_project\\A_Jalil_S_M-master\\PersonalInfo\\urls.py", line 29, in <module>\r
[Thu Oct 13 12:09:52.159007 2022] [wsgi:error] [pid 5036:tid 1880] [client 192.168.101.70:52153]     path('utils', utils, name='utils'),\r
[Thu Oct 13 12:09:52.159007 2022] [wsgi:error] [pid 5036:tid 1880] [client 192.168.101.70:52153] NameError: name 'utils' is not defined\r
[Thu Oct 13 12:10:30.465473 2022] [wsgi:error] [pid 5036:tid 1880] [client 192.168.101.70:52162] Internal Server Error: /fd/\r
[Thu Oct 13 12:10:30.465473 2022] [wsgi:error] [pid 5036:tid 1880] [client 192.168.101.70:52162] Traceback (most recent call last):\r
[Thu Oct 13 12:10:30.465473 2022] [wsgi:error] [pid 5036:tid 1880] [client 192.168.101.70:52162]   File "E:\\Python_project\\CharterIns\\venv\\Lib\\site-packages\\django\\core\\handlers\\exception.py", line 55, in inner\r
[Thu Oct 13 12:10:30.465473 2022] [wsgi:error] [pid 5036:tid 1880] [client 192.168.101.70:52162]     response = get_response(request)\r
[Thu Oct 13 12:10:30.465473 2022] [wsgi:error] [pid 5036:tid 1880] [client 192.168.101.70:52162]   File "E:\\Python_project\\CharterIns\\venv\\Lib\\site-packages\\django\\core\\handlers\\base.py", line 181, in _get_response\r
[Thu Oct 13 12:10:30.465473 2022] [wsgi:error] [pid 5036:tid 1880] [client 192.168.101.70:52162]     callback, callback_args, callback_kwargs = self.resolve_request(request)\r
[Thu Oct 13 12:10:30.465473 2022] [wsgi:error] [pid 5036:tid 1880] [client 192.168.101.70:52162]   File "E:\\Python_project\\CharterIns\\venv\\Lib\\site-packages\\django\\core\\handlers\\base.py", line 313, in resolve_request\r
[Thu Oct 13 12:10:30.465473 2022] [wsgi:error] [pid 5036:tid 1880] [client 192.168.101.70:52162]     resolver_match = resolver.resolve(request.path_info)\r
[Thu Oct 13 12:10:30.465473 2022] [wsgi:error] [pid 5036:tid 1880] [client 192.168.101.70:52162]   File "E:\\Python_project\\CharterIns\\venv\\Lib\\site-packages\\django\\urls\\resolvers.py", line 649, in resolve\r
[Thu Oct 13 12:10:30.465473 2022] [wsgi:error] [pid 5036:tid 1880] [client 192.168.101.70:52162]     for pattern in self.url_patterns:\r
[Thu Oct 13 12:10:30.465473 2022] [wsgi:error] [pid 5036:tid 1880] [client 192.168.101.70:52162]   File "E:\\Python_project\\CharterIns\\venv\\Lib\\site-packages\\django\\utils\\functional.py", line 49, in __get__\r
[Thu Oct 13 12:10:30.465473 2022] [wsgi:error] [pid 5036:tid 1880] [client 192.168.101.70:52162]     res = instance.__dict__[self.name] = self.func(instance)\r
[Thu Oct 13 12:10:30.465473 2022] [wsgi:error] [pid 5036:tid 1880] [client 192.168.101.70:52162]   File "E:\\Python_project\\CharterIns\\venv\\Lib\\site-packages\\django\\urls\\resolvers.py", line 696, in url_patterns\r
[Thu Oct 13 12:10:30.465473 2022] [wsgi:error] [pid 5036:tid 1880] [client 192.168.101.70:52162]     patterns = getattr(self.urlconf_module, "urlpatterns", self.urlconf_module)\r
[Thu Oct 13 12:10:30.465473 2022] [wsgi:error] [pid 5036:tid 1880] [client 192.168.101.70:52162]   File "E:\\Python_project\\CharterIns\\venv\\Lib\\site-packages\\django\\utils\\functional.py", line 49, in __get__\r
[Thu Oct 13 12:10:30.465473 2022] [wsgi:error] [pid 5036:tid 1880] [client 192.168.101.70:52162]     res = instance.__dict__[self.name] = self.func(instance)\r
[Thu Oct 13 12:10:30.465473 2022] [wsgi:error] [pid 5036:tid 1880] [client 192.168.101.70:52162]   File "E:\\Python_project\\CharterIns\\venv\\Lib\\site-packages\\django\\urls\\resolvers.py", line 689, in urlconf_module\r
[Thu Oct 13 12:10:30.465473 2022] [wsgi:error] [pid 5036:tid 1880] [client 192.168.101.70:52162]     return import_module(self.urlconf_name)\r
[Thu Oct 13 12:10:30.465473 2022] [wsgi:error] [pid 5036:tid 1880] [client 192.168.101.70:52162]   File "C:\\Users\\Administrator\\AppData\\Local\\Programs\\Python\\Python310\\Lib\\importlib\\__init__.py", line 126, in import_module\r
[Thu Oct 13 12:10:30.465473 2022] [wsgi:error] [pid 5036:tid 1880] [client 192.168.101.70:52162]     return _bootstrap._gcd_import(name[level:], package, level)\r
[Thu Oct 13 12:10:30.465473 2022] [wsgi:error] [pid 5036:tid 1880] [client 192.168.101.70:52162]   File "<frozen importlib._bootstrap>", line 1050, in _gcd_import\r
[Thu Oct 13 12:10:30.465473 2022] [wsgi:error] [pid 5036:tid 1880] [client 192.168.101.70:52162]   File "<frozen importlib._bootstrap>", line 1027, in _find_and_load\r
[Thu Oct 13 12:10:30.465473 2022] [wsgi:error] [pid 5036:tid 1880] [client 192.168.101.70:52162]   File "<frozen importlib._bootstrap>", line 1006, in _find_and_load_unlocked\r
[Thu Oct 13 12:10:30.465473 2022] [wsgi:error] [pid 5036:tid 1880] [client 192.168.101.70:52162]   File "<frozen importlib._bootstrap>", line 688, in _load_unlocked\r
[Thu Oct 13 12:10:30.465473 2022] [wsgi:error] [pid 5036:tid 1880] [client 192.168.101.70:52162]   File "<frozen importlib._bootstrap_external>", line 883, in exec_module\r
[Thu Oct 13 12:10:30.465473 2022] [wsgi:error] [pid 5036:tid 1880] [client 192.168.101.70:52162]   File "<frozen importlib._bootstrap>", line 241, in _call_with_frames_removed\r
[Thu Oct 13 12:10:30.465473 2022] [wsgi:error] [pid 5036:tid 1880] [client 192.168.101.70:52162]   File "E:\\Python_project\\A_Jalil_S_M-master\\A_Jalil_S_M\\urls.py", line 25, in <module>\r
[Thu Oct 13 12:10:30.465473 2022] [wsgi:error] [pid 5036:tid 1880] [client 192.168.101.70:52162]     path('',include('PersonalInfo.urls')),\r
[Thu Oct 13 12:10:30.465473 2022] [wsgi:error] [pid 5036:tid 1880] [client 192.168.101.70:52162]   File "E:\\Python_project\\CharterIns\\venv\\Lib\\site-packages\\django\\urls\\conf.py", line 38, in include\r
[Thu Oct 13 12:10:30.466472 2022] [wsgi:error] [pid 5036:tid 1880] [client 192.168.101.70:52162]     urlconf_module = import_module(urlconf_module)\r
[Thu Oct 13 12:10:30.466472 2022] [wsgi:error] [pid 5036:tid 1880] [client 192.168.101.70:52162]   File "C:\\Users\\Administrator\\AppData\\Local\\Programs\\Python\\Python310\\Lib\\importlib\\__init__.py", line 126, in import_module\r
[Thu Oct 13 12:10:30.466472 2022] [wsgi:error] [pid 5036:tid 1880] [client 192.168.101.70:52162]     return _bootstrap._gcd_import(name[level:], package, level)\r
[Thu Oct 13 12:10:30.466472 2022] [wsgi:error] [pid 5036:tid 1880] [client 192.168.101.70:52162]   File "<frozen importlib._bootstrap>", line 1050, in _gcd_import\r
[Thu Oct 13 12:10:30.466472 2022] [wsgi:error] [pid 5036:tid 1880] [client 192.168.101.70:52162]   File "<frozen importlib._bootstrap>", line 1027, in _find_and_load\r
[Thu Oct 13 12:10:30.466472 2022] [wsgi:error] [pid 5036:tid 1880] [client 192.168.101.70:52162]   File "<frozen importlib._bootstrap>", line 1006, in _find_and_load_unlocked\r
[Thu Oct 13 12:10:30.466472 2022] [wsgi:error] [pid 5036:tid 1880] [client 192.168.101.70:52162]   File "<frozen importlib._bootstrap>", line 688, in _load_unlocked\r
[Thu Oct 13 12:10:30.466472 2022] [wsgi:error] [pid 5036:tid 1880] [client 192.168.101.70:52162]   File "<frozen importlib._bootstrap_external>", line 883, in exec_module\r
[Thu Oct 13 12:10:30.466472 2022] [wsgi:error] [pid 5036:tid 1880] [client 192.168.101.70:52162]   File "<frozen importlib._bootstrap>", line 241, in _call_with_frames_removed\r
[Thu Oct 13 12:10:30.466472 2022] [wsgi:error] [pid 5036:tid 1880] [client 192.168.101.70:52162]   File "E:\\Python_project\\A_Jalil_S_M-master\\PersonalInfo\\urls.py", line 29, in <module>\r
[Thu Oct 13 12:10:30.466472 2022] [wsgi:error] [pid 5036:tid 1880] [client 192.168.101.70:52162]     path('utils', utils, name='utils'),\r
[Thu Oct 13 12:10:30.466472 2022] [wsgi:error] [pid 5036:tid 1880] [client 192.168.101.70:52162] NameError: name 'utils' is not defined\r
[Thu Oct 13 12:10:36.826331 2022] [wsgi:error] [pid 5036:tid 1880] [client 192.168.101.70:52165] Internal Server Error: /fd/\r
[Thu Oct 13 12:10:36.826331 2022] [wsgi:error] [pid 5036:tid 1880] [client 192.168.101.70:52165] Traceback (most recent call last):\r
[Thu Oct 13 12:10:36.826331 2022] [wsgi:error] [pid 5036:tid 1880] [client 192.168.101.70:52165]   File "E:\\Python_project\\CharterIns\\venv\\Lib\\site-packages\\django\\core\\handlers\\exception.py", line 55, in inner\r
[Thu Oct 13 12:10:36.826331 2022] [wsgi:error] [pid 5036:tid 1880] [client 192.168.101.70:52165]     response = get_response(request)\r
[Thu Oct 13 12:10:36.827333 2022] [wsgi:error] [pid 5036:tid 1880] [client 192.168.101.70:52165]   File "E:\\Python_project\\CharterIns\\venv\\Lib\\site-packages\\django\\core\\handlers\\base.py", line 181, in _get_response\r
[Thu Oct 13 12:10:36.827333 2022] [wsgi:error] [pid 5036:tid 1880] [client 192.168.101.70:52165]     callback, callback_args, callback_kwargs = self.resolve_request(request)\r
[Thu Oct 13 12:10:36.827333 2022] [wsgi:error] [pid 5036:tid 1880] [client 192.168.101.70:52165]   File "E:\\Python_project\\CharterIns\\venv\\Lib\\site-packages\\django\\core\\handlers\\base.py", line 313, in resolve_request\r
[Thu Oct 13 12:10:36.827333 2022] [wsgi:error] [pid 5036:tid 1880] [client 192.168.101.70:52165]     resolver_match = resolver.resolve(request.path_info)\r
[Thu Oct 13 12:10:36.827333 2022] [wsgi:error] [pid 5036:tid 1880] [client 192.168.101.70:52165]   File "E:\\Python_project\\CharterIns\\venv\\Lib\\site-packages\\django\\urls\\resolvers.py", line 649, in resolve\r
[Thu Oct 13 12:10:36.827333 2022] [wsgi:error] [pid 5036:tid 1880] [client 192.168.101.70:52165]     for pattern in self.url_patterns:\r
[Thu Oct 13 12:10:36.827333 2022] [wsgi:error] [pid 5036:tid 1880] [client 192.168.101.70:52165]   File "E:\\Python_project\\CharterIns\\venv\\Lib\\site-packages\\django\\utils\\functional.py", line 49, in __get__\r
[Thu Oct 13 12:10:36.827333 2022] [wsgi:error] [pid 5036:tid 1880] [client 192.168.101.70:52165]     res = instance.__dict__[self.name] = self.func(instance)\r
[Thu Oct 13 12:10:36.827333 2022] [wsgi:error] [pid 5036:tid 1880] [client 192.168.101.70:52165]   File "E:\\Python_project\\CharterIns\\venv\\Lib\\site-packages\\django\\urls\\resolvers.py", line 696, in url_patterns\r
[Thu Oct 13 12:10:36.827333 2022] [wsgi:error] [pid 5036:tid 1880] [client 192.168.101.70:52165]     patterns = getattr(self.urlconf_module, "urlpatterns", self.urlconf_module)\r
[Thu Oct 13 12:10:36.827333 2022] [wsgi:error] [pid 5036:tid 1880] [client 192.168.101.70:52165]   File "E:\\Python_project\\CharterIns\\venv\\Lib\\site-packages\\django\\utils\\functional.py", line 49, in __get__\r
[Thu Oct 13 12:10:36.827333 2022] [wsgi:error] [pid 5036:tid 1880] [client 192.168.101.70:52165]     res = instance.__dict__[self.name] = self.func(instance)\r
[Thu Oct 13 12:10:36.827333 2022] [wsgi:error] [pid 5036:tid 1880] [client 192.168.101.70:52165]   File "E:\\Python_project\\CharterIns\\venv\\Lib\\site-packages\\django\\urls\\resolvers.py", line 689, in urlconf_module\r
[Thu Oct 13 12:10:36.827333 2022] [wsgi:error] [pid 5036:tid 1880] [client 192.168.101.70:52165]     return import_module(self.urlconf_name)\r
[Thu Oct 13 12:10:36.827333 2022] [wsgi:error] [pid 5036:tid 1880] [client 192.168.101.70:52165]   File "C:\\Users\\Administrator\\AppData\\Local\\Programs\\Python\\Python310\\Lib\\importlib\\__init__.py", line 126, in import_module\r
[Thu Oct 13 12:10:36.827333 2022] [wsgi:error] [pid 5036:tid 1880] [client 192.168.101.70:52165]     return _bootstrap._gcd_import(name[level:], package, level)\r
[Thu Oct 13 12:10:36.827333 2022] [wsgi:error] [pid 5036:tid 1880] [client 192.168.101.70:52165]   File "<frozen importlib._bootstrap>", line 1050, in _gcd_import\r
[Thu Oct 13 12:10:36.827333 2022] [wsgi:error] [pid 5036:tid 1880] [client 192.168.101.70:52165]   File "<frozen importlib._bootstrap>", line 1027, in _find_and_load\r
[Thu Oct 13 12:10:36.827333 2022] [wsgi:error] [pid 5036:tid 1880] [client 192.168.101.70:52165]   File "<frozen importlib._bootstrap>", line 1006, in _find_and_load_unlocked\r
[Thu Oct 13 12:10:36.827333 2022] [wsgi:error] [pid 5036:tid 1880] [client 192.168.101.70:52165]   File "<frozen importlib._bootstrap>", line 688, in _load_unlocked\r
[Thu Oct 13 12:10:36.827333 2022] [wsgi:error] [pid 5036:tid 1880] [client 192.168.101.70:52165]   File "<frozen importlib._bootstrap_external>", line 883, in exec_module\r
[Thu Oct 13 12:10:36.827333 2022] [wsgi:error] [pid 5036:tid 1880] [client 192.168.101.70:52165]   File "<frozen importlib._bootstrap>", line 241, in _call_with_frames_removed\r
[Thu Oct 13 12:10:36.827333 2022] [wsgi:error] [pid 5036:tid 1880] [client 192.168.101.70:52165]   File "E:\\Python_project\\A_Jalil_S_M-master\\A_Jalil_S_M\\urls.py", line 25, in <module>\r
[Thu Oct 13 12:10:36.827333 2022] [wsgi:error] [pid 5036:tid 1880] [client 192.168.101.70:52165]     path('',include('PersonalInfo.urls')),\r
[Thu Oct 13 12:10:36.827333 2022] [wsgi:error] [pid 5036:tid 1880] [client 192.168.101.70:52165]   File "E:\\Python_project\\CharterIns\\venv\\Lib\\site-packages\\django\\urls\\conf.py", line 38, in include\r
[Thu Oct 13 12:10:36.827333 2022] [wsgi:error] [pid 5036:tid 1880] [client 192.168.101.70:52165]     urlconf_module = import_module(urlconf_module)\r
[Thu Oct 13 12:10:36.827333 2022] [wsgi:error] [pid 5036:tid 1880] [client 192.168.101.70:52165]   File "C:\\Users\\Administrator\\AppData\\Local\\Programs\\Python\\Python310\\Lib\\importlib\\__init__.py", line 126, in import_module\r
[Thu Oct 13 12:10:36.827333 2022] [wsgi:error] [pid 5036:tid 1880] [client 192.168.101.70:52165]     return _bootstrap._gcd_import(name[level:], package, level)\r
[Thu Oct 13 12:10:36.827333 2022] [wsgi:error] [pid 5036:tid 1880] [client 192.168.101.70:52165]   File "<frozen importlib._bootstrap>", line 1050, in _gcd_import\r
[Thu Oct 13 12:10:36.827333 2022] [wsgi:error] [pid 5036:tid 1880] [client 192.168.101.70:52165]   File "<frozen importlib._bootstrap>", line 1027, in _find_and_load\r
[Thu Oct 13 12:10:36.827333 2022] [wsgi:error] [pid 5036:tid 1880] [client 192.168.101.70:52165]   File "<frozen importlib._bootstrap>", line 1006, in _find_and_load_unlocked\r
[Thu Oct 13 12:10:36.827333 2022] [wsgi:error] [pid 5036:tid 1880] [client 192.168.101.70:52165]   File "<frozen importlib._bootstrap>", line 688, in _load_unlocked\r
[Thu Oct 13 12:10:36.827333 2022] [wsgi:error] [pid 5036:tid 1880] [client 192.168.101.70:52165]   File "<frozen importlib._bootstrap_external>", line 883, in exec_module\r
[Thu Oct 13 12:10:36.827333 2022] [wsgi:error] [pid 5036:tid 1880] [client 192.168.101.70:52165]   File "<frozen importlib._bootstrap>", line 241, in _call_with_frames_removed\r
[Thu Oct 13 12:10:36.828331 2022] [wsgi:error] [pid 5036:tid 1880] [client 192.168.101.70:52165]   File "E:\\Python_project\\A_Jalil_S_M-master\\PersonalInfo\\urls.py", line 29, in <module>\r
[Thu Oct 13 12:10:36.828331 2022] [wsgi:error] [pid 5036:tid 1880] [client 192.168.101.70:52165]     path('utils', utils, name='utils'),\r
[Thu Oct 13 12:10:36.828331 2022] [wsgi:error] [pid 5036:tid 1880] [client 192.168.101.70:52165] NameError: name 'utils' is not defined\r
[Thu Oct 13 12:12:40.417400 2022] [wsgi:error] [pid 5036:tid 1880] [client 192.168.94.110:53575] Internal Server Error: /fd/landing\r, referer: http://10.99.99.201:8012/fd
[Thu Oct 13 12:12:40.417400 2022] [wsgi:error] [pid 5036:tid 1880] [client 192.168.94.110:53575] Traceback (most recent call last):\r, referer: http://10.99.99.201:8012/fd
[Thu Oct 13 12:12:40.417400 2022] [wsgi:error] [pid 5036:tid 1880] [client 192.168.94.110:53575]   File "E:\\Python_project\\CharterIns\\venv\\Lib\\site-packages\\django\\core\\handlers\\exception.py", line 55, in inner\r, referer: http://10.99.99.201:8012/fd
[Thu Oct 13 12:12:40.417400 2022] [wsgi:error] [pid 5036:tid 1880] [client 192.168.94.110:53575]     response = get_response(request)\r, referer: http://10.99.99.201:8012/fd
[Thu Oct 13 12:12:40.417400 2022] [wsgi:error] [pid 5036:tid 1880] [client 192.168.94.110:53575]   File "E:\\Python_project\\CharterIns\\venv\\Lib\\site-packages\\django\\core\\handlers\\base.py", line 197, in _get_response\r, referer: http://10.99.99.201:8012/fd
[Thu Oct 13 12:12:40.417400 2022] [wsgi:error] [pid 5036:tid 1880] [client 192.168.94.110:53575]     response = wrapped_callback(request, *callback_args, **callback_kwargs)\r, referer: http://10.99.99.201:8012/fd
[Thu Oct 13 12:12:40.417400 2022] [wsgi:error] [pid 5036:tid 1880] [client 192.168.94.110:53575]   File "E:\\Python_project\\A_Jalil_S_M-master\\PersonalInfo\\views.py", line 425, in landing\r, referer: http://10.99.99.201:8012/fd
[Thu Oct 13 12:12:40.417400 2022] [wsgi:error] [pid 5036:tid 1880] [client 192.168.94.110:53575]     return render(request,'landing.html')\r, referer: http://10.99.99.201:8012/fd
[Thu Oct 13 12:12:40.417400 2022] [wsgi:error] [pid 5036:tid 1880] [client 192.168.94.110:53575]   File "E:\\Python_project\\CharterIns\\venv\\Lib\\site-packages\\django\\shortcuts.py", line 24, in render\r, referer: http://10.99.99.201:8012/fd
[Thu Oct 13 12:12:40.417400 2022] [wsgi:error] [pid 5036:tid 1880] [client 192.168.94.110:53575]     content = loader.render_to_string(template_name, context, request, using=using)\r, referer: http://10.99.99.201:8012/fd
[Thu Oct 13 12:12:40.417400 2022] [wsgi:error] [pid 5036:tid 1880] [client 192.168.94.110:53575]   File "E:\\Python_project\\CharterIns\\venv\\Lib\\site-packages\\django\\template\\loader.py", line 62, in render_to_string\r, referer: http://10.99.99.201:8012/fd
[Thu Oct 13 12:12:40.417400 2022] [wsgi:error] [pid 5036:tid 1880] [client 192.168.94.110:53575]     return template.render(context, request)\r, referer: http://10.99.99.201:8012/fd
[Thu Oct 13 12:12:40.417400 2022] [wsgi:error] [pid 5036:tid 1880] [client 192.168.94.110:53575]   File "E:\\Python_project\\CharterIns\\venv\\Lib\\site-packages\\django\\template\\backends\\django.py", line 62, in render\r, referer: http://10.99.99.201:8012/fd
[Thu Oct 13 12:12:40.417400 2022] [wsgi:error] [pid 5036:tid 1880] [client 192.168.94.110:53575]     return self.template.render(context)\r, referer: http://10.99.99.201:8012/fd
[Thu Oct 13 12:12:40.417400 2022] [wsgi:error] [pid 5036:tid 1880] [client 192.168.94.110:53575]   File "E:\\Python_project\\CharterIns\\venv\\Lib\\site-packages\\django\\template\\base.py", line 175, in render\r, referer: http://10.99.99.201:8012/fd
[Thu Oct 13 12:12:40.417400 2022] [wsgi:error] [pid 5036:tid 1880] [client 192.168.94.110:53575]     return self._render(context)\r, referer: http://10.99.99.201:8012/fd
[Thu Oct 13 12:12:40.417400 2022] [wsgi:error] [pid 5036:tid 1880] [client 192.168.94.110:53575]   File "E:\\Python_project\\CharterIns\\venv\\Lib\\site-packages\\django\\template\\base.py", line 167, in _render\r, referer: http://10.99.99.201:8012/fd
[Thu Oct 13 12:12:40.417400 2022] [wsgi:error] [pid 5036:tid 1880] [client 192.168.94.110:53575]     return self.nodelist.render(context)\r, referer: http://10.99.99.201:8012/fd
[Thu Oct 13 12:12:40.417400 2022] [wsgi:error] [pid 5036:tid 1880] [client 192.168.94.110:53575]   File "E:\\Python_project\\CharterIns\\venv\\Lib\\site-packages\\django\\template\\base.py", line 1000, in render\r, referer: http://10.99.99.201:8012/fd
[Thu Oct 13 12:12:40.417400 2022] [wsgi:error] [pid 5036:tid 1880] [client 192.168.94.110:53575]     return SafeString("".join([node.render_annotated(context) for node in self]))\r, referer: http://10.99.99.201:8012/fd
[Thu Oct 13 12:12:40.417400 2022] [wsgi:error] [pid 5036:tid 1880] [client 192.168.94.110:53575]   File "E:\\Python_project\\CharterIns\\venv\\Lib\\site-packages\\django\\template\\base.py", line 1000, in <listcomp>\r, referer: http://10.99.99.201:8012/fd
[Thu Oct 13 12:12:40.417400 2022] [wsgi:error] [pid 5036:tid 1880] [client 192.168.94.110:53575]     return SafeString("".join([node.render_annotated(context) for node in self]))\r, referer: http://10.99.99.201:8012/fd
[Thu Oct 13 12:12:40.417400 2022] [wsgi:error] [pid 5036:tid 1880] [client 192.168.94.110:53575]   File "E:\\Python_project\\CharterIns\\venv\\Lib\\site-packages\\django\\template\\base.py", line 958, in render_annotated\r, referer: http://10.99.99.201:8012/fd
[Thu Oct 13 12:12:40.417400 2022] [wsgi:error] [pid 5036:tid 1880] [client 192.168.94.110:53575]     return self.render(context)\r, referer: http://10.99.99.201:8012/fd
[Thu Oct 13 12:12:40.417400 2022] [wsgi:error] [pid 5036:tid 1880] [client 192.168.94.110:53575]   File "E:\\Python_project\\CharterIns\\venv\\Lib\\site-packages\\django\\template\\loader_tags.py", line 157, in render\r, referer: http://10.99.99.201:8012/fd
[Thu Oct 13 12:12:40.417400 2022] [wsgi:error] [pid 5036:tid 1880] [client 192.168.94.110:53575]     return compiled_parent._render(context)\r, referer: http://10.99.99.201:8012/fd
[Thu Oct 13 12:12:40.417400 2022] [wsgi:error] [pid 5036:tid 1880] [client 192.168.94.110:53575]   File "E:\\Python_project\\CharterIns\\venv\\Lib\\site-packages\\django\\template\\base.py", line 167, in _render\r, referer: http://10.99.99.201:8012/fd
[Thu Oct 13 12:12:40.417400 2022] [wsgi:error] [pid 5036:tid 1880] [client 192.168.94.110:53575]     return self.nodelist.render(context)\r, referer: http://10.99.99.201:8012/fd
[Thu Oct 13 12:12:40.417400 2022] [wsgi:error] [pid 5036:tid 1880] [client 192.168.94.110:53575]   File "E:\\Python_project\\CharterIns\\venv\\Lib\\site-packages\\django\\template\\base.py", line 1000, in render\r, referer: http://10.99.99.201:8012/fd
[Thu Oct 13 12:12:40.417400 2022] [wsgi:error] [pid 5036:tid 1880] [client 192.168.94.110:53575]     return SafeString("".join([node.render_annotated(context) for node in self]))\r, referer: http://10.99.99.201:8012/fd
[Thu Oct 13 12:12:40.417400 2022] [wsgi:error] [pid 5036:tid 1880] [client 192.168.94.110:53575]   File "E:\\Python_project\\CharterIns\\venv\\Lib\\site-packages\\django\\template\\base.py", line 1000, in <listcomp>\r, referer: http://10.99.99.201:8012/fd
[Thu Oct 13 12:12:40.417400 2022] [wsgi:error] [pid 5036:tid 1880] [client 192.168.94.110:53575]     return SafeString("".join([node.render_annotated(context) for node in self]))\r, referer: http://10.99.99.201:8012/fd
[Thu Oct 13 12:12:40.417400 2022] [wsgi:error] [pid 5036:tid 1880] [client 192.168.94.110:53575]   File "E:\\Python_project\\CharterIns\\venv\\Lib\\site-packages\\django\\template\\base.py", line 958, in render_annotated\r, referer: http://10.99.99.201:8012/fd
[Thu Oct 13 12:12:40.417400 2022] [wsgi:error] [pid 5036:tid 1880] [client 192.168.94.110:53575]     return self.render(context)\r, referer: http://10.99.99.201:8012/fd
[Thu Oct 13 12:12:40.417400 2022] [wsgi:error] [pid 5036:tid 1880] [client 192.168.94.110:53575]   File "E:\\Python_project\\CharterIns\\venv\\Lib\\site-packages\\django\\template\\defaulttags.py", line 472, in render\r, referer: http://10.99.99.201:8012/fd
[Thu Oct 13 12:12:40.417400 2022] [wsgi:error] [pid 5036:tid 1880] [client 192.168.94.110:53575]     url = reverse(view_name, args=args, kwargs=kwargs, current_app=current_app)\r, referer: http://10.99.99.201:8012/fd
[Thu Oct 13 12:12:40.417400 2022] [wsgi:error] [pid 5036:tid 1880] [client 192.168.94.110:53575]   File "E:\\Python_project\\CharterIns\\venv\\Lib\\site-packages\\django\\urls\\base.py", line 88, in reverse\r, referer: http://10.99.99.201:8012/fd
[Thu Oct 13 12:12:40.418400 2022] [wsgi:error] [pid 5036:tid 1880] [client 192.168.94.110:53575]     return resolver._reverse_with_prefix(view, prefix, *args, **kwargs)\r, referer: http://10.99.99.201:8012/fd
[Thu Oct 13 12:12:40.418400 2022] [wsgi:error] [pid 5036:tid 1880] [client 192.168.94.110:53575]   File "E:\\Python_project\\CharterIns\\venv\\Lib\\site-packages\\django\\urls\\resolvers.py", line 802, in _reverse_with_prefix\r, referer: http://10.99.99.201:8012/fd
[Thu Oct 13 12:12:40.418400 2022] [wsgi:error] [pid 5036:tid 1880] [client 192.168.94.110:53575]     raise NoReverseMatch(msg)\r, referer: http://10.99.99.201:8012/fd
[Thu Oct 13 12:12:40.418400 2022] [wsgi:error] [pid 5036:tid 1880] [client 192.168.94.110:53575] django.urls.exceptions.NoReverseMatch: Reverse for 'files_upload' not found. 'files_upload' is not a valid view function or pattern name.\r, referer: http://10.99.99.201:8012/fd
[Thu Oct 13 12:15:10.914467 2022] [wsgi:error] [pid 5036:tid 1880] [client 192.168.94.110:53878] Internal Server Error: /fd/landing\r, referer: http://10.99.99.201:8012/fd
[Thu Oct 13 12:15:10.914467 2022] [wsgi:error] [pid 5036:tid 1880] [client 192.168.94.110:53878] Traceback (most recent call last):\r, referer: http://10.99.99.201:8012/fd
[Thu Oct 13 12:15:10.914467 2022] [wsgi:error] [pid 5036:tid 1880] [client 192.168.94.110:53878]   File "E:\\Python_project\\CharterIns\\venv\\Lib\\site-packages\\django\\core\\handlers\\exception.py", line 55, in inner\r, referer: http://10.99.99.201:8012/fd
[Thu Oct 13 12:15:10.914467 2022] [wsgi:error] [pid 5036:tid 1880] [client 192.168.94.110:53878]     response = get_response(request)\r, referer: http://10.99.99.201:8012/fd
[Thu Oct 13 12:15:10.914467 2022] [wsgi:error] [pid 5036:tid 1880] [client 192.168.94.110:53878]   File "E:\\Python_project\\CharterIns\\venv\\Lib\\site-packages\\django\\core\\handlers\\base.py", line 197, in _get_response\r, referer: http://10.99.99.201:8012/fd
[Thu Oct 13 12:15:10.914467 2022] [wsgi:error] [pid 5036:tid 1880] [client 192.168.94.110:53878]     response = wrapped_callback(request, *callback_args, **callback_kwargs)\r, referer: http://10.99.99.201:8012/fd
[Thu Oct 13 12:15:10.914467 2022] [wsgi:error] [pid 5036:tid 1880] [client 192.168.94.110:53878]   File "E:\\Python_project\\A_Jalil_S_M-master\\PersonalInfo\\views.py", line 425, in landing\r, referer: http://10.99.99.201:8012/fd
[Thu Oct 13 12:15:10.914467 2022] [wsgi:error] [pid 5036:tid 1880] [client 192.168.94.110:53878]     except:\r, referer: http://10.99.99.201:8012/fd
[Thu Oct 13 12:15:10.914467 2022] [wsgi:error] [pid 5036:tid 1880] [client 192.168.94.110:53878]   File "E:\\Python_project\\CharterIns\\venv\\Lib\\site-packages\\django\\shortcuts.py", line 24, in render\r, referer: http://10.99.99.201:8012/fd
[Thu Oct 13 12:15:10.914467 2022] [wsgi:error] [pid 5036:tid 1880] [client 192.168.94.110:53878]     content = loader.render_to_string(template_name, context, request, using=using)\r, referer: http://10.99.99.201:8012/fd
[Thu Oct 13 12:15:10.914467 2022] [wsgi:error] [pid 5036:tid 1880] [client 192.168.94.110:53878]   File "E:\\Python_project\\CharterIns\\venv\\Lib\\site-packages\\django\\template\\loader.py", line 62, in render_to_string\r, referer: http://10.99.99.201:8012/fd
[Thu Oct 13 12:15:10.914467 2022] [wsgi:error] [pid 5036:tid 1880] [client 192.168.94.110:53878]     return template.render(context, request)\r, referer: http://10.99.99.201:8012/fd
[Thu Oct 13 12:15:10.914467 2022] [wsgi:error] [pid 5036:tid 1880] [client 192.168.94.110:53878]   File "E:\\Python_project\\CharterIns\\venv\\Lib\\site-packages\\django\\template\\backends\\django.py", line 62, in render\r, referer: http://10.99.99.201:8012/fd
[Thu Oct 13 12:15:10.914467 2022] [wsgi:error] [pid 5036:tid 1880] [client 192.168.94.110:53878]     return self.template.render(context)\r, referer: http://10.99.99.201:8012/fd
[Thu Oct 13 12:15:10.914467 2022] [wsgi:error] [pid 5036:tid 1880] [client 192.168.94.110:53878]   File "E:\\Python_project\\CharterIns\\venv\\Lib\\site-packages\\django\\template\\base.py", line 175, in render\r, referer: http://10.99.99.201:8012/fd
[Thu Oct 13 12:15:10.914467 2022] [wsgi:error] [pid 5036:tid 1880] [client 192.168.94.110:53878]     return self._render(context)\r, referer: http://10.99.99.201:8012/fd
[Thu Oct 13 12:15:10.914467 2022] [wsgi:error] [pid 5036:tid 1880] [client 192.168.94.110:53878]   File "E:\\Python_project\\CharterIns\\venv\\Lib\\site-packages\\django\\template\\base.py", line 167, in _render\r, referer: http://10.99.99.201:8012/fd
[Thu Oct 13 12:15:10.914467 2022] [wsgi:error] [pid 5036:tid 1880] [client 192.168.94.110:53878]     return self.nodelist.render(context)\r, referer: http://10.99.99.201:8012/fd
[Thu Oct 13 12:15:10.914467 2022] [wsgi:error] [pid 5036:tid 1880] [client 192.168.94.110:53878]   File "E:\\Python_project\\CharterIns\\venv\\Lib\\site-packages\\django\\template\\base.py", line 1000, in render\r, referer: http://10.99.99.201:8012/fd
[Thu Oct 13 12:15:10.914467 2022] [wsgi:error] [pid 5036:tid 1880] [client 192.168.94.110:53878]     return SafeString("".join([node.render_annotated(context) for node in self]))\r, referer: http://10.99.99.201:8012/fd
[Thu Oct 13 12:15:10.914467 2022] [wsgi:error] [pid 5036:tid 1880] [client 192.168.94.110:53878]   File "E:\\Python_project\\CharterIns\\venv\\Lib\\site-packages\\django\\template\\base.py", line 1000, in <listcomp>\r, referer: http://10.99.99.201:8012/fd
[Thu Oct 13 12:15:10.914467 2022] [wsgi:error] [pid 5036:tid 1880] [client 192.168.94.110:53878]     return SafeString("".join([node.render_annotated(context) for node in self]))\r, referer: http://10.99.99.201:8012/fd
[Thu Oct 13 12:15:10.914467 2022] [wsgi:error] [pid 5036:tid 1880] [client 192.168.94.110:53878]   File "E:\\Python_project\\CharterIns\\venv\\Lib\\site-packages\\django\\template\\base.py", line 958, in render_annotated\r, referer: http://10.99.99.201:8012/fd
[Thu Oct 13 12:15:10.914467 2022] [wsgi:error] [pid 5036:tid 1880] [client 192.168.94.110:53878]     return self.render(context)\r, referer: http://10.99.99.201:8012/fd
[Thu Oct 13 12:15:10.914467 2022] [wsgi:error] [pid 5036:tid 1880] [client 192.168.94.110:53878]   File "E:\\Python_project\\CharterIns\\venv\\Lib\\site-packages\\django\\template\\loader_tags.py", line 157, in render\r, referer: http://10.99.99.201:8012/fd
[Thu Oct 13 12:15:10.914467 2022] [wsgi:error] [pid 5036:tid 1880] [client 192.168.94.110:53878]     return compiled_parent._render(context)\r, referer: http://10.99.99.201:8012/fd
[Thu Oct 13 12:15:10.914467 2022] [wsgi:error] [pid 5036:tid 1880] [client 192.168.94.110:53878]   File "E:\\Python_project\\CharterIns\\venv\\Lib\\site-packages\\django\\template\\base.py", line 167, in _render\r, referer: http://10.99.99.201:8012/fd
[Thu Oct 13 12:15:10.914467 2022] [wsgi:error] [pid 5036:tid 1880] [client 192.168.94.110:53878]     return self.nodelist.render(context)\r, referer: http://10.99.99.201:8012/fd
[Thu Oct 13 12:15:10.914467 2022] [wsgi:error] [pid 5036:tid 1880] [client 192.168.94.110:53878]   File "E:\\Python_project\\CharterIns\\venv\\Lib\\site-packages\\django\\template\\base.py", line 1000, in render\r, referer: http://10.99.99.201:8012/fd
[Thu Oct 13 12:15:10.914467 2022] [wsgi:error] [pid 5036:tid 1880] [client 192.168.94.110:53878]     return SafeString("".join([node.render_annotated(context) for node in self]))\r, referer: http://10.99.99.201:8012/fd
[Thu Oct 13 12:15:10.914467 2022] [wsgi:error] [pid 5036:tid 1880] [client 192.168.94.110:53878]   File "E:\\Python_project\\CharterIns\\venv\\Lib\\site-packages\\django\\template\\base.py", line 1000, in <listcomp>\r, referer: http://10.99.99.201:8012/fd
[Thu Oct 13 12:15:10.914467 2022] [wsgi:error] [pid 5036:tid 1880] [client 192.168.94.110:53878]     return SafeString("".join([node.render_annotated(context) for node in self]))\r, referer: http://10.99.99.201:8012/fd
[Thu Oct 13 12:15:10.914467 2022] [wsgi:error] [pid 5036:tid 1880] [client 192.168.94.110:53878]   File "E:\\Python_project\\CharterIns\\venv\\Lib\\site-packages\\django\\template\\base.py", line 958, in render_annotated\r, referer: http://10.99.99.201:8012/fd
[Thu Oct 13 12:15:10.914467 2022] [wsgi:error] [pid 5036:tid 1880] [client 192.168.94.110:53878]     return self.render(context)\r, referer: http://10.99.99.201:8012/fd
[Thu Oct 13 12:15:10.914467 2022] [wsgi:error] [pid 5036:tid 1880] [client 192.168.94.110:53878]   File "E:\\Python_project\\CharterIns\\venv\\Lib\\site-packages\\django\\template\\defaulttags.py", line 472, in render\r, referer: http://10.99.99.201:8012/fd
[Thu Oct 13 12:15:10.914467 2022] [wsgi:error] [pid 5036:tid 1880] [client 192.168.94.110:53878]     url = reverse(view_name, args=args, kwargs=kwargs, current_app=current_app)\r, referer: http://10.99.99.201:8012/fd
[Thu Oct 13 12:15:10.914467 2022] [wsgi:error] [pid 5036:tid 1880] [client 192.168.94.110:53878]   File "E:\\Python_project\\CharterIns\\venv\\Lib\\site-packages\\django\\urls\\base.py", line 88, in reverse\r, referer: http://10.99.99.201:8012/fd
[Thu Oct 13 12:15:10.914467 2022] [wsgi:error] [pid 5036:tid 1880] [client 192.168.94.110:53878]     return resolver._reverse_with_prefix(view, prefix, *args, **kwargs)\r, referer: http://10.99.99.201:8012/fd
[Thu Oct 13 12:15:10.914467 2022] [wsgi:error] [pid 5036:tid 1880] [client 192.168.94.110:53878]   File "E:\\Python_project\\CharterIns\\venv\\Lib\\site-packages\\django\\urls\\resolvers.py", line 802, in _reverse_with_prefix\r, referer: http://10.99.99.201:8012/fd
[Thu Oct 13 12:15:10.914467 2022] [wsgi:error] [pid 5036:tid 1880] [client 192.168.94.110:53878]     raise NoReverseMatch(msg)\r, referer: http://10.99.99.201:8012/fd
[Thu Oct 13 12:15:10.914467 2022] [wsgi:error] [pid 5036:tid 1880] [client 192.168.94.110:53878] django.urls.exceptions.NoReverseMatch: Reverse for 'files_upload' not found. 'files_upload' is not a valid view function or pattern name.\r, referer: http://10.99.99.201:8012/fd
[Thu Oct 13 12:15:59.697714 2022] [wsgi:error] [pid 1372:tid 1884] [client 192.168.94.110:53977] Internal Server Error: /fd/files_upload\r, referer: http://10.99.99.201:8012/fd/scholarship_apply
[Thu Oct 13 12:15:59.697714 2022] [wsgi:error] [pid 1372:tid 1884] [client 192.168.94.110:53977] Traceback (most recent call last):\r, referer: http://10.99.99.201:8012/fd/scholarship_apply
[Thu Oct 13 12:15:59.697714 2022] [wsgi:error] [pid 1372:tid 1884] [client 192.168.94.110:53977]   File "E:\\Python_project\\CharterIns\\venv\\Lib\\site-packages\\django\\core\\handlers\\exception.py", line 55, in inner\r, referer: http://10.99.99.201:8012/fd/scholarship_apply
[Thu Oct 13 12:15:59.697714 2022] [wsgi:error] [pid 1372:tid 1884] [client 192.168.94.110:53977]     response = get_response(request)\r, referer: http://10.99.99.201:8012/fd/scholarship_apply
[Thu Oct 13 12:15:59.697714 2022] [wsgi:error] [pid 1372:tid 1884] [client 192.168.94.110:53977]   File "E:\\Python_project\\CharterIns\\venv\\Lib\\site-packages\\django\\core\\handlers\\base.py", line 197, in _get_response\r, referer: http://10.99.99.201:8012/fd/scholarship_apply
[Thu Oct 13 12:15:59.697714 2022] [wsgi:error] [pid 1372:tid 1884] [client 192.168.94.110:53977]     response = wrapped_callback(request, *callback_args, **callback_kwargs)\r, referer: http://10.99.99.201:8012/fd/scholarship_apply
[Thu Oct 13 12:15:59.697714 2022] [wsgi:error] [pid 1372:tid 1884] [client 192.168.94.110:53977]   File "E:\\Python_project\\A_Jalil_S_M-master\\PersonalInfo\\views.py", line 489, in model_files_upload\r, referer: http://10.99.99.201:8012/fd/scholarship_apply
[Thu Oct 13 12:15:59.697714 2022] [wsgi:error] [pid 1372:tid 1884] [client 192.168.94.110:53977]     form = FilesForm()\r, referer: http://10.99.99.201:8012/fd/scholarship_apply
[Thu Oct 13 12:15:59.697714 2022] [wsgi:error] [pid 1372:tid 1884] [client 192.168.94.110:53977] NameError: name 'FilesForm' is not defined\r, referer: http://10.99.99.201:8012/fd/scholarship_apply
[Thu Oct 13 12:17:19.257642 2022] [wsgi:error] [pid 11640:tid 1884] [client 192.168.94.110:54155] Internal Server Error: /fd/scholarship_apply\r, referer: http://10.99.99.201:8012/fd
[Thu Oct 13 12:17:19.257642 2022] [wsgi:error] [pid 11640:tid 1884] [client 192.168.94.110:54155] Traceback (most recent call last):\r, referer: http://10.99.99.201:8012/fd
[Thu Oct 13 12:17:19.257642 2022] [wsgi:error] [pid 11640:tid 1884] [client 192.168.94.110:54155]   File "E:\\Python_project\\CharterIns\\venv\\Lib\\site-packages\\django\\core\\handlers\\exception.py", line 55, in inner\r, referer: http://10.99.99.201:8012/fd
[Thu Oct 13 12:17:19.257642 2022] [wsgi:error] [pid 11640:tid 1884] [client 192.168.94.110:54155]     response = get_response(request)\r, referer: http://10.99.99.201:8012/fd
[Thu Oct 13 12:17:19.257642 2022] [wsgi:error] [pid 11640:tid 1884] [client 192.168.94.110:54155]   File "E:\\Python_project\\CharterIns\\venv\\Lib\\site-packages\\django\\utils\\deprecation.py", line 133, in __call__\r, referer: http://10.99.99.201:8012/fd
[Thu Oct 13 12:17:19.257642 2022] [wsgi:error] [pid 11640:tid 1884] [client 192.168.94.110:54155]     response = self.process_request(request)\r, referer: http://10.99.99.201:8012/fd
[Thu Oct 13 12:17:19.257642 2022] [wsgi:error] [pid 11640:tid 1884] [client 192.168.94.110:54155]   File "E:\\Python_project\\CharterIns\\venv\\Lib\\site-packages\\django\\middleware\\common.py", line 53, in process_request\r, referer: http://10.99.99.201:8012/fd
[Thu Oct 13 12:17:19.257642 2022] [wsgi:error] [pid 11640:tid 1884] [client 192.168.94.110:54155]     if self.should_redirect_with_slash(request):\r, referer: http://10.99.99.201:8012/fd
[Thu Oct 13 12:17:19.257642 2022] [wsgi:error] [pid 11640:tid 1884] [client 192.168.94.110:54155]   File "E:\\Python_project\\CharterIns\\venv\\Lib\\site-packages\\django\\middleware\\common.py", line 70, in should_redirect_with_slash\r, referer: http://10.99.99.201:8012/fd
[Thu Oct 13 12:17:19.257642 2022] [wsgi:error] [pid 11640:tid 1884] [client 192.168.94.110:54155]     if not is_valid_path(request.path_info, urlconf):\r, referer: http://10.99.99.201:8012/fd
[Thu Oct 13 12:17:19.257642 2022] [wsgi:error] [pid 11640:tid 1884] [client 192.168.94.110:54155]   File "E:\\Python_project\\CharterIns\\venv\\Lib\\site-packages\\django\\urls\\base.py", line 155, in is_valid_path\r, referer: http://10.99.99.201:8012/fd
[Thu Oct 13 12:17:19.257642 2022] [wsgi:error] [pid 11640:tid 1884] [client 192.168.94.110:54155]     return resolve(path, urlconf)\r, referer: http://10.99.99.201:8012/fd
[Thu Oct 13 12:17:19.257642 2022] [wsgi:error] [pid 11640:tid 1884] [client 192.168.94.110:54155]   File "E:\\Python_project\\CharterIns\\venv\\Lib\\site-packages\\django\\urls\\base.py", line 24, in resolve\r, referer: http://10.99.99.201:8012/fd
[Thu Oct 13 12:17:19.257642 2022] [wsgi:error] [pid 11640:tid 1884] [client 192.168.94.110:54155]     return get_resolver(urlconf).resolve(path)\r, referer: http://10.99.99.201:8012/fd
[Thu Oct 13 12:17:19.257642 2022] [wsgi:error] [pid 11640:tid 1884] [client 192.168.94.110:54155]   File "E:\\Python_project\\CharterIns\\venv\\Lib\\site-packages\\django\\urls\\resolvers.py", line 649, in resolve\r, referer: http://10.99.99.201:8012/fd
[Thu Oct 13 12:17:19.257642 2022] [wsgi:error] [pid 11640:tid 1884] [client 192.168.94.110:54155]     for pattern in self.url_patterns:\r, referer: http://10.99.99.201:8012/fd
[Thu Oct 13 12:17:19.257642 2022] [wsgi:error] [pid 11640:tid 1884] [client 192.168.94.110:54155]   File "E:\\Python_project\\CharterIns\\venv\\Lib\\site-packages\\django\\utils\\functional.py", line 49, in __get__\r, referer: http://10.99.99.201:8012/fd
[Thu Oct 13 12:17:19.257642 2022] [wsgi:error] [pid 11640:tid 1884] [client 192.168.94.110:54155]     res = instance.__dict__[self.name] = self.func(instance)\r, referer: http://10.99.99.201:8012/fd
[Thu Oct 13 12:17:19.257642 2022] [wsgi:error] [pid 11640:tid 1884] [client 192.168.94.110:54155]   File "E:\\Python_project\\CharterIns\\venv\\Lib\\site-packages\\django\\urls\\resolvers.py", line 696, in url_patterns\r, referer: http://10.99.99.201:8012/fd
[Thu Oct 13 12:17:19.257642 2022] [wsgi:error] [pid 11640:tid 1884] [client 192.168.94.110:54155]     patterns = getattr(self.urlconf_module, "urlpatterns", self.urlconf_module)\r, referer: http://10.99.99.201:8012/fd
[Thu Oct 13 12:17:19.257642 2022] [wsgi:error] [pid 11640:tid 1884] [client 192.168.94.110:54155]   File "E:\\Python_project\\CharterIns\\venv\\Lib\\site-packages\\django\\utils\\functional.py", line 49, in __get__\r, referer: http://10.99.99.201:8012/fd
[Thu Oct 13 12:17:19.257642 2022] [wsgi:error] [pid 11640:tid 1884] [client 192.168.94.110:54155]     res = instance.__dict__[self.name] = self.func(instance)\r, referer: http://10.99.99.201:8012/fd
[Thu Oct 13 12:17:19.257642 2022] [wsgi:error] [pid 11640:tid 1884] [client 192.168.94.110:54155]   File "E:\\Python_project\\CharterIns\\venv\\Lib\\site-packages\\django\\urls\\resolvers.py", line 689, in urlconf_module\r, referer: http://10.99.99.201:8012/fd
[Thu Oct 13 12:17:19.257642 2022] [wsgi:error] [pid 11640:tid 1884] [client 192.168.94.110:54155]     return import_module(self.urlconf_name)\r, referer: http://10.99.99.201:8012/fd
[Thu Oct 13 12:17:19.257642 2022] [wsgi:error] [pid 11640:tid 1884] [client 192.168.94.110:54155]   File "C:\\Users\\Administrator\\AppData\\Local\\Programs\\Python\\Python310\\Lib\\importlib\\__init__.py", line 126, in import_module\r, referer: http://10.99.99.201:8012/fd
[Thu Oct 13 12:17:19.257642 2022] [wsgi:error] [pid 11640:tid 1884] [client 192.168.94.110:54155]     return _bootstrap._gcd_import(name[level:], package, level)\r, referer: http://10.99.99.201:8012/fd
[Thu Oct 13 12:17:19.257642 2022] [wsgi:error] [pid 11640:tid 1884] [client 192.168.94.110:54155]   File "<frozen importlib._bootstrap>", line 1050, in _gcd_import\r, referer: http://10.99.99.201:8012/fd
[Thu Oct 13 12:17:19.257642 2022] [wsgi:error] [pid 11640:tid 1884] [client 192.168.94.110:54155]   File "<frozen importlib._bootstrap>", line 1027, in _find_and_load\r, referer: http://10.99.99.201:8012/fd
[Thu Oct 13 12:17:19.257642 2022] [wsgi:error] [pid 11640:tid 1884] [client 192.168.94.110:54155]   File "<frozen importlib._bootstrap>", line 1006, in _find_and_load_unlocked\r, referer: http://10.99.99.201:8012/fd
[Thu Oct 13 12:17:19.257642 2022] [wsgi:error] [pid 11640:tid 1884] [client 192.168.94.110:54155]   File "<frozen importlib._bootstrap>", line 688, in _load_unlocked\r, referer: http://10.99.99.201:8012/fd
[Thu Oct 13 12:17:19.257642 2022] [wsgi:error] [pid 11640:tid 1884] [client 192.168.94.110:54155]   File "<frozen importlib._bootstrap_external>", line 883, in exec_module\r, referer: http://10.99.99.201:8012/fd
[Thu Oct 13 12:17:19.257642 2022] [wsgi:error] [pid 11640:tid 1884] [client 192.168.94.110:54155]   File "<frozen importlib._bootstrap>", line 241, in _call_with_frames_removed\r, referer: http://10.99.99.201:8012/fd
[Thu Oct 13 12:17:19.258642 2022] [wsgi:error] [pid 11640:tid 1884] [client 192.168.94.110:54155]   File "E:\\Python_project\\A_Jalil_S_M-master\\A_Jalil_S_M\\urls.py", line 25, in <module>\r, referer: http://10.99.99.201:8012/fd
[Thu Oct 13 12:17:19.258642 2022] [wsgi:error] [pid 11640:tid 1884] [client 192.168.94.110:54155]     path('',include('PersonalInfo.urls')),\r, referer: http://10.99.99.201:8012/fd
[Thu Oct 13 12:17:19.258642 2022] [wsgi:error] [pid 11640:tid 1884] [client 192.168.94.110:54155]   File "E:\\Python_project\\CharterIns\\venv\\Lib\\site-packages\\django\\urls\\conf.py", line 38, in include\r, referer: http://10.99.99.201:8012/fd
[Thu Oct 13 12:17:19.258642 2022] [wsgi:error] [pid 11640:tid 1884] [client 192.168.94.110:54155]     urlconf_module = import_module(urlconf_module)\r, referer: http://10.99.99.201:8012/fd
[Thu Oct 13 12:17:19.258642 2022] [wsgi:error] [pid 11640:tid 1884] [client 192.168.94.110:54155]   File "C:\\Users\\Administrator\\AppData\\Local\\Programs\\Python\\Python310\\Lib\\importlib\\__init__.py", line 126, in import_module\r, referer: http://10.99.99.201:8012/fd
[Thu Oct 13 12:17:19.258642 2022] [wsgi:error] [pid 11640:tid 1884] [client 192.168.94.110:54155]     return _bootstrap._gcd_import(name[level:], package, level)\r, referer: http://10.99.99.201:8012/fd
[Thu Oct 13 12:17:19.258642 2022] [wsgi:error] [pid 11640:tid 1884] [client 192.168.94.110:54155]   File "<frozen importlib._bootstrap>", line 1050, in _gcd_import\r, referer: http://10.99.99.201:8012/fd
[Thu Oct 13 12:17:19.258642 2022] [wsgi:error] [pid 11640:tid 1884] [client 192.168.94.110:54155]   File "<frozen importlib._bootstrap>", line 1027, in _find_and_load\r, referer: http://10.99.99.201:8012/fd
[Thu Oct 13 12:17:19.258642 2022] [wsgi:error] [pid 11640:tid 1884] [client 192.168.94.110:54155]   File "<frozen importlib._bootstrap>", line 1006, in _find_and_load_unlocked\r, referer: http://10.99.99.201:8012/fd
[Thu Oct 13 12:17:19.258642 2022] [wsgi:error] [pid 11640:tid 1884] [client 192.168.94.110:54155]   File "<frozen importlib._bootstrap>", line 688, in _load_unlocked\r, referer: http://10.99.99.201:8012/fd
[Thu Oct 13 12:17:19.258642 2022] [wsgi:error] [pid 11640:tid 1884] [client 192.168.94.110:54155]   File "<frozen importlib._bootstrap_external>", line 883, in exec_module\r, referer: http://10.99.99.201:8012/fd
[Thu Oct 13 12:17:19.258642 2022] [wsgi:error] [pid 11640:tid 1884] [client 192.168.94.110:54155]   File "<frozen importlib._bootstrap>", line 241, in _call_with_frames_removed\r, referer: http://10.99.99.201:8012/fd
[Thu Oct 13 12:17:19.258642 2022] [wsgi:error] [pid 11640:tid 1884] [client 192.168.94.110:54155]   File "E:\\Python_project\\A_Jalil_S_M-master\\PersonalInfo\\urls.py", line 4, in <module>\r, referer: http://10.99.99.201:8012/fd
[Thu Oct 13 12:17:19.258642 2022] [wsgi:error] [pid 11640:tid 1884] [client 192.168.94.110:54155]     from .views import *\r, referer: http://10.99.99.201:8012/fd
[Thu Oct 13 12:17:19.258642 2022] [wsgi:error] [pid 11640:tid 1884] [client 192.168.94.110:54155]   File "E:\\Python_project\\A_Jalil_S_M-master\\PersonalInfo\\views.py", line 6, in <module>\r, referer: http://10.99.99.201:8012/fd
[Thu Oct 13 12:17:19.258642 2022] [wsgi:error] [pid 11640:tid 1884] [client 192.168.94.110:54155]     from .forms import *\r, referer: http://10.99.99.201:8012/fd
[Thu Oct 13 12:17:19.258642 2022] [wsgi:error] [pid 11640:tid 1884] [client 192.168.94.110:54155]   File "E:\\Python_project\\A_Jalil_S_M-master\\PersonalInfo\\forms.py", line 29, in <module>\r, referer: http://10.99.99.201:8012/fd
[Thu Oct 13 12:17:19.258642 2022] [wsgi:error] [pid 11640:tid 1884] [client 192.168.94.110:54155]     class FilesForm(forms.ModelForm):\r, referer: http://10.99.99.201:8012/fd
[Thu Oct 13 12:17:19.258642 2022] [wsgi:error] [pid 11640:tid 1884] [client 192.168.94.110:54155]   File "E:\\Python_project\\A_Jalil_S_M-master\\PersonalInfo\\forms.py", line 30, in FilesForm\r, referer: http://10.99.99.201:8012/fd
[Thu Oct 13 12:17:19.258642 2022] [wsgi:error] [pid 11640:tid 1884] [client 192.168.94.110:54155]     class Meta:\r, referer: http://10.99.99.201:8012/fd
[Thu Oct 13 12:17:19.258642 2022] [wsgi:error] [pid 11640:tid 1884] [client 192.168.94.110:54155]   File "E:\\Python_project\\A_Jalil_S_M-master\\PersonalInfo\\forms.py", line 31, in Meta\r, referer: http://10.99.99.201:8012/fd
[Thu Oct 13 12:17:19.258642 2022] [wsgi:error] [pid 11640:tid 1884] [client 192.168.94.110:54155]     model = Files\r, referer: http://10.99.99.201:8012/fd
[Thu Oct 13 12:17:19.258642 2022] [wsgi:error] [pid 11640:tid 1884] [client 192.168.94.110:54155] NameError: name 'Files' is not defined\r, referer: http://10.99.99.201:8012/fd
[Thu Oct 13 12:17:20.837697 2022] [wsgi:error] [pid 11640:tid 1880] [client 192.168.94.110:54156] Internal Server Error: /fd/files_upload\r, referer: http://10.99.99.201:8012/fd/scholarship_apply
[Thu Oct 13 12:17:20.837697 2022] [wsgi:error] [pid 11640:tid 1880] [client 192.168.94.110:54156] Traceback (most recent call last):\r, referer: http://10.99.99.201:8012/fd/scholarship_apply
[Thu Oct 13 12:17:20.837697 2022] [wsgi:error] [pid 11640:tid 1880] [client 192.168.94.110:54156]   File "E:\\Python_project\\CharterIns\\venv\\Lib\\site-packages\\django\\core\\handlers\\exception.py", line 55, in inner\r, referer: http://10.99.99.201:8012/fd/scholarship_apply
[Thu Oct 13 12:17:20.837697 2022] [wsgi:error] [pid 11640:tid 1880] [client 192.168.94.110:54156]     response = get_response(request)\r, referer: http://10.99.99.201:8012/fd/scholarship_apply
[Thu Oct 13 12:17:20.837697 2022] [wsgi:error] [pid 11640:tid 1880] [client 192.168.94.110:54156]   File "E:\\Python_project\\CharterIns\\venv\\Lib\\site-packages\\django\\utils\\deprecation.py", line 133, in __call__\r, referer: http://10.99.99.201:8012/fd/scholarship_apply
[Thu Oct 13 12:17:20.837697 2022] [wsgi:error] [pid 11640:tid 1880] [client 192.168.94.110:54156]     response = self.process_request(request)\r, referer: http://10.99.99.201:8012/fd/scholarship_apply
[Thu Oct 13 12:17:20.837697 2022] [wsgi:error] [pid 11640:tid 1880] [client 192.168.94.110:54156]   File "E:\\Python_project\\CharterIns\\venv\\Lib\\site-packages\\django\\middleware\\common.py", line 53, in process_request\r, referer: http://10.99.99.201:8012/fd/scholarship_apply
[Thu Oct 13 12:17:20.837697 2022] [wsgi:error] [pid 11640:tid 1880] [client 192.168.94.110:54156]     if self.should_redirect_with_slash(request):\r, referer: http://10.99.99.201:8012/fd/scholarship_apply
[Thu Oct 13 12:17:20.838697 2022] [wsgi:error] [pid 11640:tid 1880] [client 192.168.94.110:54156]   File "E:\\Python_project\\CharterIns\\venv\\Lib\\site-packages\\django\\middleware\\common.py", line 70, in should_redirect_with_slash\r, referer: http://10.99.99.201:8012/fd/scholarship_apply
[Thu Oct 13 12:17:20.838697 2022] [wsgi:error] [pid 11640:tid 1880] [client 192.168.94.110:54156]     if not is_valid_path(request.path_info, urlconf):\r, referer: http://10.99.99.201:8012/fd/scholarship_apply
[Thu Oct 13 12:17:20.838697 2022] [wsgi:error] [pid 11640:tid 1880] [client 192.168.94.110:54156]   File "E:\\Python_project\\CharterIns\\venv\\Lib\\site-packages\\django\\urls\\base.py", line 155, in is_valid_path\r, referer: http://10.99.99.201:8012/fd/scholarship_apply
[Thu Oct 13 12:17:20.838697 2022] [wsgi:error] [pid 11640:tid 1880] [client 192.168.94.110:54156]     return resolve(path, urlconf)\r, referer: http://10.99.99.201:8012/fd/scholarship_apply
[Thu Oct 13 12:17:20.838697 2022] [wsgi:error] [pid 11640:tid 1880] [client 192.168.94.110:54156]   File "E:\\Python_project\\CharterIns\\venv\\Lib\\site-packages\\django\\urls\\base.py", line 24, in resolve\r, referer: http://10.99.99.201:8012/fd/scholarship_apply
[Thu Oct 13 12:17:20.838697 2022] [wsgi:error] [pid 11640:tid 1880] [client 192.168.94.110:54156]     return get_resolver(urlconf).resolve(path)\r, referer: http://10.99.99.201:8012/fd/scholarship_apply
[Thu Oct 13 12:17:20.838697 2022] [wsgi:error] [pid 11640:tid 1880] [client 192.168.94.110:54156]   File "E:\\Python_project\\CharterIns\\venv\\Lib\\site-packages\\django\\urls\\resolvers.py", line 649, in resolve\r, referer: http://10.99.99.201:8012/fd/scholarship_apply
[Thu Oct 13 12:17:20.838697 2022] [wsgi:error] [pid 11640:tid 1880] [client 192.168.94.110:54156]     for pattern in self.url_patterns:\r, referer: http://10.99.99.201:8012/fd/scholarship_apply
[Thu Oct 13 12:17:20.838697 2022] [wsgi:error] [pid 11640:tid 1880] [client 192.168.94.110:54156]   File "E:\\Python_project\\CharterIns\\venv\\Lib\\site-packages\\django\\utils\\functional.py", line 49, in __get__\r, referer: http://10.99.99.201:8012/fd/scholarship_apply
[Thu Oct 13 12:17:20.838697 2022] [wsgi:error] [pid 11640:tid 1880] [client 192.168.94.110:54156]     res = instance.__dict__[self.name] = self.func(instance)\r, referer: http://10.99.99.201:8012/fd/scholarship_apply
[Thu Oct 13 12:17:20.838697 2022] [wsgi:error] [pid 11640:tid 1880] [client 192.168.94.110:54156]   File "E:\\Python_project\\CharterIns\\venv\\Lib\\site-packages\\django\\urls\\resolvers.py", line 696, in url_patterns\r, referer: http://10.99.99.201:8012/fd/scholarship_apply
[Thu Oct 13 12:17:20.838697 2022] [wsgi:error] [pid 11640:tid 1880] [client 192.168.94.110:54156]     patterns = getattr(self.urlconf_module, "urlpatterns", self.urlconf_module)\r, referer: http://10.99.99.201:8012/fd/scholarship_apply
[Thu Oct 13 12:17:20.838697 2022] [wsgi:error] [pid 11640:tid 1880] [client 192.168.94.110:54156]   File "E:\\Python_project\\CharterIns\\venv\\Lib\\site-packages\\django\\utils\\functional.py", line 49, in __get__\r, referer: http://10.99.99.201:8012/fd/scholarship_apply
[Thu Oct 13 12:17:20.838697 2022] [wsgi:error] [pid 11640:tid 1880] [client 192.168.94.110:54156]     res = instance.__dict__[self.name] = self.func(instance)\r, referer: http://10.99.99.201:8012/fd/scholarship_apply
[Thu Oct 13 12:17:20.838697 2022] [wsgi:error] [pid 11640:tid 1880] [client 192.168.94.110:54156]   File "E:\\Python_project\\CharterIns\\venv\\Lib\\site-packages\\django\\urls\\resolvers.py", line 689, in urlconf_module\r, referer: http://10.99.99.201:8012/fd/scholarship_apply
[Thu Oct 13 12:17:20.838697 2022] [wsgi:error] [pid 11640:tid 1880] [client 192.168.94.110:54156]     return import_module(self.urlconf_name)\r, referer: http://10.99.99.201:8012/fd/scholarship_apply
[Thu Oct 13 12:17:20.838697 2022] [wsgi:error] [pid 11640:tid 1880] [client 192.168.94.110:54156]   File "C:\\Users\\Administrator\\AppData\\Local\\Programs\\Python\\Python310\\Lib\\importlib\\__init__.py", line 126, in import_module\r, referer: http://10.99.99.201:8012/fd/scholarship_apply
[Thu Oct 13 12:17:20.838697 2022] [wsgi:error] [pid 11640:tid 1880] [client 192.168.94.110:54156]     return _bootstrap._gcd_import(name[level:], package, level)\r, referer: http://10.99.99.201:8012/fd/scholarship_apply
[Thu Oct 13 12:17:20.838697 2022] [wsgi:error] [pid 11640:tid 1880] [client 192.168.94.110:54156]   File "<frozen importlib._bootstrap>", line 1050, in _gcd_import\r, referer: http://10.99.99.201:8012/fd/scholarship_apply
[Thu Oct 13 12:17:20.838697 2022] [wsgi:error] [pid 11640:tid 1880] [client 192.168.94.110:54156]   File "<frozen importlib._bootstrap>", line 1027, in _find_and_load\r, referer: http://10.99.99.201:8012/fd/scholarship_apply
[Thu Oct 13 12:17:20.838697 2022] [wsgi:error] [pid 11640:tid 1880] [client 192.168.94.110:54156]   File "<frozen importlib._bootstrap>", line 1006, in _find_and_load_unlocked\r, referer: http://10.99.99.201:8012/fd/scholarship_apply
[Thu Oct 13 12:17:20.838697 2022] [wsgi:error] [pid 11640:tid 1880] [client 192.168.94.110:54156]   File "<frozen importlib._bootstrap>", line 688, in _load_unlocked\r, referer: http://10.99.99.201:8012/fd/scholarship_apply
[Thu Oct 13 12:17:20.838697 2022] [wsgi:error] [pid 11640:tid 1880] [client 192.168.94.110:54156]   File "<frozen importlib._bootstrap_external>", line 883, in exec_module\r, referer: http://10.99.99.201:8012/fd/scholarship_apply
[Thu Oct 13 12:17:20.838697 2022] [wsgi:error] [pid 11640:tid 1880] [client 192.168.94.110:54156]   File "<frozen importlib._bootstrap>", line 241, in _call_with_frames_removed\r, referer: http://10.99.99.201:8012/fd/scholarship_apply
[Thu Oct 13 12:17:20.838697 2022] [wsgi:error] [pid 11640:tid 1880] [client 192.168.94.110:54156]   File "E:\\Python_project\\A_Jalil_S_M-master\\A_Jalil_S_M\\urls.py", line 25, in <module>\r, referer: http://10.99.99.201:8012/fd/scholarship_apply
[Thu Oct 13 12:17:20.838697 2022] [wsgi:error] [pid 11640:tid 1880] [client 192.168.94.110:54156]     path('',include('PersonalInfo.urls')),\r, referer: http://10.99.99.201:8012/fd/scholarship_apply
[Thu Oct 13 12:17:20.838697 2022] [wsgi:error] [pid 11640:tid 1880] [client 192.168.94.110:54156]   File "E:\\Python_project\\CharterIns\\venv\\Lib\\site-packages\\django\\urls\\conf.py", line 38, in include\r, referer: http://10.99.99.201:8012/fd/scholarship_apply
[Thu Oct 13 12:17:20.838697 2022] [wsgi:error] [pid 11640:tid 1880] [client 192.168.94.110:54156]     urlconf_module = import_module(urlconf_module)\r, referer: http://10.99.99.201:8012/fd/scholarship_apply
[Thu Oct 13 12:17:20.838697 2022] [wsgi:error] [pid 11640:tid 1880] [client 192.168.94.110:54156]   File "C:\\Users\\Administrator\\AppData\\Local\\Programs\\Python\\Python310\\Lib\\importlib\\__init__.py", line 126, in import_module\r, referer: http://10.99.99.201:8012/fd/scholarship_apply
[Thu Oct 13 12:17:20.838697 2022] [wsgi:error] [pid 11640:tid 1880] [client 192.168.94.110:54156]     return _bootstrap._gcd_import(name[level:], package, level)\r, referer: http://10.99.99.201:8012/fd/scholarship_apply
[Thu Oct 13 12:17:20.838697 2022] [wsgi:error] [pid 11640:tid 1880] [client 192.168.94.110:54156]   File "<frozen importlib._bootstrap>", line 1050, in _gcd_import\r, referer: http://10.99.99.201:8012/fd/scholarship_apply
[Thu Oct 13 12:17:20.838697 2022] [wsgi:error] [pid 11640:tid 1880] [client 192.168.94.110:54156]   File "<frozen importlib._bootstrap>", line 1027, in _find_and_load\r, referer: http://10.99.99.201:8012/fd/scholarship_apply
[Thu Oct 13 12:17:20.838697 2022] [wsgi:error] [pid 11640:tid 1880] [client 192.168.94.110:54156]   File "<frozen importlib._bootstrap>", line 1006, in _find_and_load_unlocked\r, referer: http://10.99.99.201:8012/fd/scholarship_apply
[Thu Oct 13 12:17:20.838697 2022] [wsgi:error] [pid 11640:tid 1880] [client 192.168.94.110:54156]   File "<frozen importlib._bootstrap>", line 688, in _load_unlocked\r, referer: http://10.99.99.201:8012/fd/scholarship_apply
[Thu Oct 13 12:17:20.839696 2022] [wsgi:error] [pid 11640:tid 1880] [client 192.168.94.110:54156]   File "<frozen importlib._bootstrap_external>", line 883, in exec_module\r, referer: http://10.99.99.201:8012/fd/scholarship_apply
[Thu Oct 13 12:17:20.839696 2022] [wsgi:error] [pid 11640:tid 1880] [client 192.168.94.110:54156]   File "<frozen importlib._bootstrap>", line 241, in _call_with_frames_removed\r, referer: http://10.99.99.201:8012/fd/scholarship_apply
[Thu Oct 13 12:17:20.839696 2022] [wsgi:error] [pid 11640:tid 1880] [client 192.168.94.110:54156]   File "E:\\Python_project\\A_Jalil_S_M-master\\PersonalInfo\\urls.py", line 4, in <module>\r, referer: http://10.99.99.201:8012/fd/scholarship_apply
[Thu Oct 13 12:17:20.839696 2022] [wsgi:error] [pid 11640:tid 1880] [client 192.168.94.110:54156]     from .views import *\r, referer: http://10.99.99.201:8012/fd/scholarship_apply
[Thu Oct 13 12:17:20.839696 2022] [wsgi:error] [pid 11640:tid 1880] [client 192.168.94.110:54156]   File "E:\\Python_project\\A_Jalil_S_M-master\\PersonalInfo\\views.py", line 6, in <module>\r, referer: http://10.99.99.201:8012/fd/scholarship_apply
[Thu Oct 13 12:17:20.839696 2022] [wsgi:error] [pid 11640:tid 1880] [client 192.168.94.110:54156]     from .forms import *\r, referer: http://10.99.99.201:8012/fd/scholarship_apply
[Thu Oct 13 12:17:20.839696 2022] [wsgi:error] [pid 11640:tid 1880] [client 192.168.94.110:54156]   File "E:\\Python_project\\A_Jalil_S_M-master\\PersonalInfo\\forms.py", line 29, in <module>\r, referer: http://10.99.99.201:8012/fd/scholarship_apply
[Thu Oct 13 12:17:20.839696 2022] [wsgi:error] [pid 11640:tid 1880] [client 192.168.94.110:54156]     class FilesForm(forms.ModelForm):\r, referer: http://10.99.99.201:8012/fd/scholarship_apply
[Thu Oct 13 12:17:20.839696 2022] [wsgi:error] [pid 11640:tid 1880] [client 192.168.94.110:54156]   File "E:\\Python_project\\A_Jalil_S_M-master\\PersonalInfo\\forms.py", line 30, in FilesForm\r, referer: http://10.99.99.201:8012/fd/scholarship_apply
[Thu Oct 13 12:17:20.839696 2022] [wsgi:error] [pid 11640:tid 1880] [client 192.168.94.110:54156]     class Meta:\r, referer: http://10.99.99.201:8012/fd/scholarship_apply
[Thu Oct 13 12:17:20.839696 2022] [wsgi:error] [pid 11640:tid 1880] [client 192.168.94.110:54156]   File "E:\\Python_project\\A_Jalil_S_M-master\\PersonalInfo\\forms.py", line 31, in Meta\r, referer: http://10.99.99.201:8012/fd/scholarship_apply
[Thu Oct 13 12:17:20.839696 2022] [wsgi:error] [pid 11640:tid 1880] [client 192.168.94.110:54156]     model = Files\r, referer: http://10.99.99.201:8012/fd/scholarship_apply
[Thu Oct 13 12:17:20.839696 2022] [wsgi:error] [pid 11640:tid 1880] [client 192.168.94.110:54156] NameError: name 'Files' is not defined\r, referer: http://10.99.99.201:8012/fd/scholarship_apply
[Thu Oct 13 12:18:50.287766 2022] [wsgi:error] [pid 7192:tid 1884] [client 192.168.94.110:54341] Internal Server Error: /fd/files_upload\r, referer: http://10.99.99.201:8012/fd/scholarship_apply
[Thu Oct 13 12:18:50.287766 2022] [wsgi:error] [pid 7192:tid 1884] [client 192.168.94.110:54341] Traceback (most recent call last):\r, referer: http://10.99.99.201:8012/fd/scholarship_apply
[Thu Oct 13 12:18:50.287766 2022] [wsgi:error] [pid 7192:tid 1884] [client 192.168.94.110:54341]   File "E:\\Python_project\\CharterIns\\venv\\Lib\\site-packages\\django\\core\\handlers\\exception.py", line 55, in inner\r, referer: http://10.99.99.201:8012/fd/scholarship_apply
[Thu Oct 13 12:18:50.287766 2022] [wsgi:error] [pid 7192:tid 1884] [client 192.168.94.110:54341]     response = get_response(request)\r, referer: http://10.99.99.201:8012/fd/scholarship_apply
[Thu Oct 13 12:18:50.287766 2022] [wsgi:error] [pid 7192:tid 1884] [client 192.168.94.110:54341]   File "E:\\Python_project\\CharterIns\\venv\\Lib\\site-packages\\django\\core\\handlers\\base.py", line 197, in _get_response\r, referer: http://10.99.99.201:8012/fd/scholarship_apply
[Thu Oct 13 12:18:50.287766 2022] [wsgi:error] [pid 7192:tid 1884] [client 192.168.94.110:54341]     response = wrapped_callback(request, *callback_args, **callback_kwargs)\r, referer: http://10.99.99.201:8012/fd/scholarship_apply
[Thu Oct 13 12:18:50.287766 2022] [wsgi:error] [pid 7192:tid 1884] [client 192.168.94.110:54341]   File "E:\\Python_project\\A_Jalil_S_M-master\\PersonalInfo\\views.py", line 497, in model_files_upload\r, referer: http://10.99.99.201:8012/fd/scholarship_apply
[Thu Oct 13 12:18:50.287766 2022] [wsgi:error] [pid 7192:tid 1884] [client 192.168.94.110:54341]     return render(request, 'documents.html', {'form': form,'files_obj':files_obj})\r, referer: http://10.99.99.201:8012/fd/scholarship_apply
[Thu Oct 13 12:18:50.287766 2022] [wsgi:error] [pid 7192:tid 1884] [client 192.168.94.110:54341]   File "E:\\Python_project\\CharterIns\\venv\\Lib\\site-packages\\django\\shortcuts.py", line 24, in render\r, referer: http://10.99.99.201:8012/fd/scholarship_apply
[Thu Oct 13 12:18:50.288767 2022] [wsgi:error] [pid 7192:tid 1884] [client 192.168.94.110:54341]     content = loader.render_to_string(template_name, context, request, using=using)\r, referer: http://10.99.99.201:8012/fd/scholarship_apply
[Thu Oct 13 12:18:50.288767 2022] [wsgi:error] [pid 7192:tid 1884] [client 192.168.94.110:54341]   File "E:\\Python_project\\CharterIns\\venv\\Lib\\site-packages\\django\\template\\loader.py", line 61, in render_to_string\r, referer: http://10.99.99.201:8012/fd/scholarship_apply
[Thu Oct 13 12:18:50.288767 2022] [wsgi:error] [pid 7192:tid 1884] [client 192.168.94.110:54341]     template = get_template(template_name, using=using)\r, referer: http://10.99.99.201:8012/fd/scholarship_apply
[Thu Oct 13 12:18:50.288767 2022] [wsgi:error] [pid 7192:tid 1884] [client 192.168.94.110:54341]   File "E:\\Python_project\\CharterIns\\venv\\Lib\\site-packages\\django\\template\\loader.py", line 19, in get_template\r, referer: http://10.99.99.201:8012/fd/scholarship_apply
[Thu Oct 13 12:18:50.288767 2022] [wsgi:error] [pid 7192:tid 1884] [client 192.168.94.110:54341]     raise TemplateDoesNotExist(template_name, chain=chain)\r, referer: http://10.99.99.201:8012/fd/scholarship_apply
[Thu Oct 13 12:18:50.288767 2022] [wsgi:error] [pid 7192:tid 1884] [client 192.168.94.110:54341] django.template.exceptions.TemplateDoesNotExist: documents.html\r, referer: http://10.99.99.201:8012/fd/scholarship_apply
[Thu Oct 13 12:20:49.153720 2022] [wsgi:error] [pid 8396:tid 1880] [client 192.168.94.110:54566] <QuerySet [<Files: Files object (1)>]>\r, referer: http://10.99.99.201:8012/fd/files_upload
[Thu Oct 13 12:21:06.271075 2022] [wsgi:error] [pid 8396:tid 1884] [client 192.168.94.110:54600] Internal Server Error: /fd/education\r, referer: http://10.99.99.201:8012/fd/files_upload
[Thu Oct 13 12:21:06.271075 2022] [wsgi:error] [pid 8396:tid 1884] [client 192.168.94.110:54600] Traceback (most recent call last):\r, referer: http://10.99.99.201:8012/fd/files_upload
[Thu Oct 13 12:21:06.271075 2022] [wsgi:error] [pid 8396:tid 1884] [client 192.168.94.110:54600]   File "E:\\Python_project\\CharterIns\\venv\\Lib\\site-packages\\django\\core\\handlers\\exception.py", line 55, in inner\r, referer: http://10.99.99.201:8012/fd/files_upload
[Thu Oct 13 12:21:06.271075 2022] [wsgi:error] [pid 8396:tid 1884] [client 192.168.94.110:54600]     response = get_response(request)\r, referer: http://10.99.99.201:8012/fd/files_upload
[Thu Oct 13 12:21:06.271075 2022] [wsgi:error] [pid 8396:tid 1884] [client 192.168.94.110:54600]   File "E:\\Python_project\\CharterIns\\venv\\Lib\\site-packages\\django\\core\\handlers\\base.py", line 197, in _get_response\r, referer: http://10.99.99.201:8012/fd/files_upload
[Thu Oct 13 12:21:06.271075 2022] [wsgi:error] [pid 8396:tid 1884] [client 192.168.94.110:54600]     response = wrapped_callback(request, *callback_args, **callback_kwargs)\r, referer: http://10.99.99.201:8012/fd/files_upload
[Thu Oct 13 12:21:06.271075 2022] [wsgi:error] [pid 8396:tid 1884] [client 192.168.94.110:54600]   File "E:\\Python_project\\A_Jalil_S_M-master\\PersonalInfo\\views.py", line 378, in education\r, referer: http://10.99.99.201:8012/fd/files_upload
[Thu Oct 13 12:21:06.271075 2022] [wsgi:error] [pid 8396:tid 1884] [client 192.168.94.110:54600]     Districts_obj=Districts.objects.all()\r, referer: http://10.99.99.201:8012/fd/files_upload
[Thu Oct 13 12:21:06.271075 2022] [wsgi:error] [pid 8396:tid 1884] [client 192.168.94.110:54600] NameError: name 'Districts' is not defined\r, referer: http://10.99.99.201:8012/fd/files_upload
[Thu Oct 13 12:23:32.105002 2022] [wsgi:error] [pid 7628:tid 1880] [client 192.168.94.110:54875] Internal Server Error: /fd/income\r, referer: http://10.99.99.201:8012/fd/income
[Thu Oct 13 12:23:32.105002 2022] [wsgi:error] [pid 7628:tid 1880] [client 192.168.94.110:54875] Traceback (most recent call last):\r, referer: http://10.99.99.201:8012/fd/income
[Thu Oct 13 12:23:32.105002 2022] [wsgi:error] [pid 7628:tid 1880] [client 192.168.94.110:54875]   File "E:\\Python_project\\CharterIns\\venv\\Lib\\site-packages\\django\\core\\handlers\\exception.py", line 55, in inner\r, referer: http://10.99.99.201:8012/fd/income
[Thu Oct 13 12:23:32.105002 2022] [wsgi:error] [pid 7628:tid 1880] [client 192.168.94.110:54875]     response = get_response(request)\r, referer: http://10.99.99.201:8012/fd/income
[Thu Oct 13 12:23:32.105002 2022] [wsgi:error] [pid 7628:tid 1880] [client 192.168.94.110:54875]   File "E:\\Python_project\\CharterIns\\venv\\Lib\\site-packages\\django\\core\\handlers\\base.py", line 197, in _get_response\r, referer: http://10.99.99.201:8012/fd/income
[Thu Oct 13 12:23:32.105002 2022] [wsgi:error] [pid 7628:tid 1880] [client 192.168.94.110:54875]     response = wrapped_callback(request, *callback_args, **callback_kwargs)\r, referer: http://10.99.99.201:8012/fd/income
[Thu Oct 13 12:23:32.105002 2022] [wsgi:error] [pid 7628:tid 1880] [client 192.168.94.110:54875]   File "E:\\Python_project\\CharterIns\\venv\\Lib\\site-packages\\django\\contrib\\auth\\decorators.py", line 23, in _wrapped_view\r, referer: http://10.99.99.201:8012/fd/income
[Thu Oct 13 12:23:32.105002 2022] [wsgi:error] [pid 7628:tid 1880] [client 192.168.94.110:54875]     return view_func(request, *args, **kwargs)\r, referer: http://10.99.99.201:8012/fd/income
[Thu Oct 13 12:23:32.105002 2022] [wsgi:error] [pid 7628:tid 1880] [client 192.168.94.110:54875]   File "E:\\Python_project\\A_Jalil_S_M-master\\PersonalInfo\\views.py", line 146, in income\r, referer: http://10.99.99.201:8012/fd/income
[Thu Oct 13 12:23:32.105002 2022] [wsgi:error] [pid 7628:tid 1880] [client 192.168.94.110:54875]     income_details_obj =Income_Details(\r, referer: http://10.99.99.201:8012/fd/income
[Thu Oct 13 12:23:32.105002 2022] [wsgi:error] [pid 7628:tid 1880] [client 192.168.94.110:54875]   File "E:\\Python_project\\CharterIns\\venv\\Lib\\site-packages\\django\\db\\models\\base.py", line 559, in __init__\r, referer: http://10.99.99.201:8012/fd/income
[Thu Oct 13 12:23:32.105002 2022] [wsgi:error] [pid 7628:tid 1880] [client 192.168.94.110:54875]     raise TypeError(\r, referer: http://10.99.99.201:8012/fd/income
[Thu Oct 13 12:23:32.105002 2022] [wsgi:error] [pid 7628:tid 1880] [client 192.168.94.110:54875] TypeError: Income_Details() got an unexpected keyword argument 'physical_disability'\r, referer: http://10.99.99.201:8012/fd/income
[Thu Oct 13 12:26:12.030237 2022] [wsgi:error] [pid 8580:tid 1880] [client 192.168.94.110:55209] 01937148058\r, referer: http://10.99.99.201:8012/fd/files_upload
[Thu Oct 13 12:31:01.366338 2022] [wsgi:error] [pid 11448:tid 1884] [client 192.168.94.110:55824] 01937148058\r, referer: http://10.99.99.201:8012/fd/files_upload
[Thu Oct 13 12:56:50.831015 2022] [wsgi:error] [pid 11448:tid 1876] [client 192.168.94.110:58821] 01937148058\r, referer: http://10.99.99.201:8012/fd/files_upload
[Thu Oct 13 13:11:02.782483 2022] [wsgi:error] [pid 5584:tid 1884] [client 192.168.94.110:61154] <QuerySet [<Files: Files object (3)>]>\r, referer: http://10.99.99.201:8012/fd/files_upload
[Thu Oct 13 13:11:11.489940 2022] [wsgi:error] [pid 5584:tid 1880] [client 192.168.94.110:61155] Not Found: /fd/documents/3305-_Response_-_Najmus_Sakib_Borson.pdf\r, referer: http://10.99.99.201:8012/fd/files_upload
[Thu Oct 13 13:11:18.224832 2022] [wsgi:error] [pid 5584:tid 1884] [client 192.168.94.110:61183] 01798599869\r, referer: http://10.99.99.201:8012/fd/files_upload
[Thu Oct 13 13:13:12.351547 2022] [wsgi:error] [pid 5584:tid 1884] [client 192.168.94.110:61431] 01798599869\r, referer: http://10.99.99.201:8012/fd/income
[Thu Oct 13 13:14:25.479502 2022] [wsgi:error] [pid 5584:tid 1884] [client 192.168.94.110:61777] 01798599869\r, referer: http://10.99.99.201:8012/fd/income
[Thu Oct 13 13:14:47.995887 2022] [wsgi:error] [pid 5584:tid 1884] [client 192.168.94.110:61842] 01798599869\r, referer: http://10.99.99.201:8012/fd/income
[Thu Oct 13 13:15:04.988545 2022] [wsgi:error] [pid 5584:tid 1884] [client 192.168.94.110:61898] Internal Server Error: /fd/education\r, referer: http://10.99.99.201:8012/fd/education
[Thu Oct 13 13:15:04.988545 2022] [wsgi:error] [pid 5584:tid 1884] [client 192.168.94.110:61898] Traceback (most recent call last):\r, referer: http://10.99.99.201:8012/fd/education
[Thu Oct 13 13:15:04.988545 2022] [wsgi:error] [pid 5584:tid 1884] [client 192.168.94.110:61898]   File "E:\\Python_project\\CharterIns\\venv\\Lib\\site-packages\\django\\utils\\datastructures.py", line 84, in __getitem__\r, referer: http://10.99.99.201:8012/fd/education
[Thu Oct 13 13:15:04.988545 2022] [wsgi:error] [pid 5584:tid 1884] [client 192.168.94.110:61898]     list_ = super().__getitem__(key)\r, referer: http://10.99.99.201:8012/fd/education
[Thu Oct 13 13:15:04.988545 2022] [wsgi:error] [pid 5584:tid 1884] [client 192.168.94.110:61898] KeyError: 'JSC_district'\r, referer: http://10.99.99.201:8012/fd/education
[Thu Oct 13 13:15:04.988545 2022] [wsgi:error] [pid 5584:tid 1884] [client 192.168.94.110:61898] \r, referer: http://10.99.99.201:8012/fd/education
[Thu Oct 13 13:15:04.988545 2022] [wsgi:error] [pid 5584:tid 1884] [client 192.168.94.110:61898] During handling of the above exception, another exception occurred:\r, referer: http://10.99.99.201:8012/fd/education
[Thu Oct 13 13:15:04.988545 2022] [wsgi:error] [pid 5584:tid 1884] [client 192.168.94.110:61898] \r, referer: http://10.99.99.201:8012/fd/education
[Thu Oct 13 13:15:04.988545 2022] [wsgi:error] [pid 5584:tid 1884] [client 192.168.94.110:61898] Traceback (most recent call last):\r, referer: http://10.99.99.201:8012/fd/education
[Thu Oct 13 13:15:04.988545 2022] [wsgi:error] [pid 5584:tid 1884] [client 192.168.94.110:61898]   File "E:\\Python_project\\CharterIns\\venv\\Lib\\site-packages\\django\\core\\handlers\\exception.py", line 55, in inner\r, referer: http://10.99.99.201:8012/fd/education
[Thu Oct 13 13:15:04.988545 2022] [wsgi:error] [pid 5584:tid 1884] [client 192.168.94.110:61898]     response = get_response(request)\r, referer: http://10.99.99.201:8012/fd/education
[Thu Oct 13 13:15:04.988545 2022] [wsgi:error] [pid 5584:tid 1884] [client 192.168.94.110:61898]   File "E:\\Python_project\\CharterIns\\venv\\Lib\\site-packages\\django\\core\\handlers\\base.py", line 197, in _get_response\r, referer: http://10.99.99.201:8012/fd/education
[Thu Oct 13 13:15:04.988545 2022] [wsgi:error] [pid 5584:tid 1884] [client 192.168.94.110:61898]     response = wrapped_callback(request, *callback_args, **callback_kwargs)\r, referer: http://10.99.99.201:8012/fd/education
[Thu Oct 13 13:15:04.988545 2022] [wsgi:error] [pid 5584:tid 1884] [client 192.168.94.110:61898]   File "E:\\Python_project\\A_Jalil_S_M-master\\PersonalInfo\\views.py", line 319, in education\r, referer: http://10.99.99.201:8012/fd/education
[Thu Oct 13 13:15:04.988545 2022] [wsgi:error] [pid 5584:tid 1884] [client 192.168.94.110:61898]     Education_obj.jsc_district=request.POST["JSC_district"]\r, referer: http://10.99.99.201:8012/fd/education
[Thu Oct 13 13:15:04.988545 2022] [wsgi:error] [pid 5584:tid 1884] [client 192.168.94.110:61898]   File "E:\\Python_project\\CharterIns\\venv\\Lib\\site-packages\\django\\utils\\datastructures.py", line 86, in __getitem__\r, referer: http://10.99.99.201:8012/fd/education
[Thu Oct 13 13:15:04.988545 2022] [wsgi:error] [pid 5584:tid 1884] [client 192.168.94.110:61898]     raise MultiValueDictKeyError(key)\r, referer: http://10.99.99.201:8012/fd/education
[Thu Oct 13 13:15:04.988545 2022] [wsgi:error] [pid 5584:tid 1884] [client 192.168.94.110:61898] django.utils.datastructures.MultiValueDictKeyError: 'JSC_district'\r, referer: http://10.99.99.201:8012/fd/education
[Thu Oct 13 13:15:38.337158 2022] [wsgi:error] [pid 5584:tid 1880] [client 192.168.94.110:61932] 01798599869\r, referer: http://10.99.99.201:8012/fd/income
[Thu Oct 13 13:15:46.160976 2022] [wsgi:error] [pid 5584:tid 1884] [client 192.168.94.110:61996] Internal Server Error: /fd/education\r, referer: http://10.99.99.201:8012/fd/education
[Thu Oct 13 13:15:46.160976 2022] [wsgi:error] [pid 5584:tid 1884] [client 192.168.94.110:61996] Traceback (most recent call last):\r, referer: http://10.99.99.201:8012/fd/education
[Thu Oct 13 13:15:46.160976 2022] [wsgi:error] [pid 5584:tid 1884] [client 192.168.94.110:61996]   File "E:\\Python_project\\CharterIns\\venv\\Lib\\site-packages\\django\\utils\\datastructures.py", line 84, in __getitem__\r, referer: http://10.99.99.201:8012/fd/education
[Thu Oct 13 13:15:46.160976 2022] [wsgi:error] [pid 5584:tid 1884] [client 192.168.94.110:61996]     list_ = super().__getitem__(key)\r, referer: http://10.99.99.201:8012/fd/education
[Thu Oct 13 13:15:46.161977 2022] [wsgi:error] [pid 5584:tid 1884] [client 192.168.94.110:61996] KeyError: 'JSC_district'\r, referer: http://10.99.99.201:8012/fd/education
[Thu Oct 13 13:15:46.161977 2022] [wsgi:error] [pid 5584:tid 1884] [client 192.168.94.110:61996] \r, referer: http://10.99.99.201:8012/fd/education
[Thu Oct 13 13:15:46.161977 2022] [wsgi:error] [pid 5584:tid 1884] [client 192.168.94.110:61996] During handling of the above exception, another exception occurred:\r, referer: http://10.99.99.201:8012/fd/education
[Thu Oct 13 13:15:46.161977 2022] [wsgi:error] [pid 5584:tid 1884] [client 192.168.94.110:61996] \r, referer: http://10.99.99.201:8012/fd/education
[Thu Oct 13 13:15:46.161977 2022] [wsgi:error] [pid 5584:tid 1884] [client 192.168.94.110:61996] Traceback (most recent call last):\r, referer: http://10.99.99.201:8012/fd/education
[Thu Oct 13 13:15:46.161977 2022] [wsgi:error] [pid 5584:tid 1884] [client 192.168.94.110:61996]   File "E:\\Python_project\\CharterIns\\venv\\Lib\\site-packages\\django\\core\\handlers\\exception.py", line 55, in inner\r, referer: http://10.99.99.201:8012/fd/education
[Thu Oct 13 13:15:46.161977 2022] [wsgi:error] [pid 5584:tid 1884] [client 192.168.94.110:61996]     response = get_response(request)\r, referer: http://10.99.99.201:8012/fd/education
[Thu Oct 13 13:15:46.161977 2022] [wsgi:error] [pid 5584:tid 1884] [client 192.168.94.110:61996]   File "E:\\Python_project\\CharterIns\\venv\\Lib\\site-packages\\django\\core\\handlers\\base.py", line 197, in _get_response\r, referer: http://10.99.99.201:8012/fd/education
[Thu Oct 13 13:15:46.161977 2022] [wsgi:error] [pid 5584:tid 1884] [client 192.168.94.110:61996]     response = wrapped_callback(request, *callback_args, **callback_kwargs)\r, referer: http://10.99.99.201:8012/fd/education
[Thu Oct 13 13:15:46.161977 2022] [wsgi:error] [pid 5584:tid 1884] [client 192.168.94.110:61996]   File "E:\\Python_project\\A_Jalil_S_M-master\\PersonalInfo\\views.py", line 319, in education\r, referer: http://10.99.99.201:8012/fd/education
[Thu Oct 13 13:15:46.161977 2022] [wsgi:error] [pid 5584:tid 1884] [client 192.168.94.110:61996]     Education_obj.jsc_district=request.POST["JSC_district"]\r, referer: http://10.99.99.201:8012/fd/education
[Thu Oct 13 13:15:46.161977 2022] [wsgi:error] [pid 5584:tid 1884] [client 192.168.94.110:61996]   File "E:\\Python_project\\CharterIns\\venv\\Lib\\site-packages\\django\\utils\\datastructures.py", line 86, in __getitem__\r, referer: http://10.99.99.201:8012/fd/education
[Thu Oct 13 13:15:46.161977 2022] [wsgi:error] [pid 5584:tid 1884] [client 192.168.94.110:61996]     raise MultiValueDictKeyError(key)\r, referer: http://10.99.99.201:8012/fd/education
[Thu Oct 13 13:15:46.161977 2022] [wsgi:error] [pid 5584:tid 1884] [client 192.168.94.110:61996] django.utils.datastructures.MultiValueDictKeyError: 'JSC_district'\r, referer: http://10.99.99.201:8012/fd/education
[Thu Oct 13 13:16:05.081830 2022] [wsgi:error] [pid 5584:tid 1880] [client 192.168.94.110:62060] 01798599869\r, referer: http://10.99.99.201:8012/fd/personal_info
[Thu Oct 13 13:18:42.717002 2022] [wsgi:error] [pid 7732:tid 1884] [client 192.168.94.110:62629] 01798599869\r, referer: http://10.99.99.201:8012/fd/image_request
[Thu Oct 13 14:58:37.271269 2022] [wsgi:error] [pid 7732:tid 1884] [client 192.168.101.70:56303] Internal Server Error: /fd/education\r, referer: http://10.99.99.201:8012/fd/education
[Thu Oct 13 14:58:37.271269 2022] [wsgi:error] [pid 7732:tid 1884] [client 192.168.101.70:56303] Traceback (most recent call last):\r, referer: http://10.99.99.201:8012/fd/education
[Thu Oct 13 14:58:37.271269 2022] [wsgi:error] [pid 7732:tid 1884] [client 192.168.101.70:56303]   File "E:\\Python_project\\CharterIns\\venv\\Lib\\site-packages\\django\\utils\\datastructures.py", line 84, in __getitem__\r, referer: http://10.99.99.201:8012/fd/education
[Thu Oct 13 14:58:37.271269 2022] [wsgi:error] [pid 7732:tid 1884] [client 192.168.101.70:56303]     list_ = super().__getitem__(key)\r, referer: http://10.99.99.201:8012/fd/education
[Thu Oct 13 14:58:37.271269 2022] [wsgi:error] [pid 7732:tid 1884] [client 192.168.101.70:56303] KeyError: 'JSC_district'\r, referer: http://10.99.99.201:8012/fd/education
[Thu Oct 13 14:58:37.271269 2022] [wsgi:error] [pid 7732:tid 1884] [client 192.168.101.70:56303] \r, referer: http://10.99.99.201:8012/fd/education
[Thu Oct 13 14:58:37.271269 2022] [wsgi:error] [pid 7732:tid 1884] [client 192.168.101.70:56303] During handling of the above exception, another exception occurred:\r, referer: http://10.99.99.201:8012/fd/education
[Thu Oct 13 14:58:37.271269 2022] [wsgi:error] [pid 7732:tid 1884] [client 192.168.101.70:56303] \r, referer: http://10.99.99.201:8012/fd/education
[Thu Oct 13 14:58:37.271269 2022] [wsgi:error] [pid 7732:tid 1884] [client 192.168.101.70:56303] Traceback (most recent call last):\r, referer: http://10.99.99.201:8012/fd/education
[Thu Oct 13 14:58:37.271269 2022] [wsgi:error] [pid 7732:tid 1884] [client 192.168.101.70:56303]   File "E:\\Python_project\\CharterIns\\venv\\Lib\\site-packages\\django\\core\\handlers\\exception.py", line 55, in inner\r, referer: http://10.99.99.201:8012/fd/education
[Thu Oct 13 14:58:37.271269 2022] [wsgi:error] [pid 7732:tid 1884] [client 192.168.101.70:56303]     response = get_response(request)\r, referer: http://10.99.99.201:8012/fd/education
[Thu Oct 13 14:58:37.271269 2022] [wsgi:error] [pid 7732:tid 1884] [client 192.168.101.70:56303]   File "E:\\Python_project\\CharterIns\\venv\\Lib\\site-packages\\django\\core\\handlers\\base.py", line 197, in _get_response\r, referer: http://10.99.99.201:8012/fd/education
[Thu Oct 13 14:58:37.271269 2022] [wsgi:error] [pid 7732:tid 1884] [client 192.168.101.70:56303]     response = wrapped_callback(request, *callback_args, **callback_kwargs)\r, referer: http://10.99.99.201:8012/fd/education
[Thu Oct 13 14:58:37.271269 2022] [wsgi:error] [pid 7732:tid 1884] [client 192.168.101.70:56303]   File "E:\\Python_project\\A_Jalil_S_M-master\\PersonalInfo\\views.py", line 319, in education\r, referer: http://10.99.99.201:8012/fd/education
[Thu Oct 13 14:58:37.271269 2022] [wsgi:error] [pid 7732:tid 1884] [client 192.168.101.70:56303]     Education_obj.jsc_district=request.POST["JSC_district"]\r, referer: http://10.99.99.201:8012/fd/education
[Thu Oct 13 14:58:37.271269 2022] [wsgi:error] [pid 7732:tid 1884] [client 192.168.101.70:56303]   File "E:\\Python_project\\CharterIns\\venv\\Lib\\site-packages\\django\\utils\\datastructures.py", line 86, in __getitem__\r, referer: http://10.99.99.201:8012/fd/education
[Thu Oct 13 14:58:37.271269 2022] [wsgi:error] [pid 7732:tid 1884] [client 192.168.101.70:56303]     raise MultiValueDictKeyError(key)\r, referer: http://10.99.99.201:8012/fd/education
[Thu Oct 13 14:58:37.271269 2022] [wsgi:error] [pid 7732:tid 1884] [client 192.168.101.70:56303] django.utils.datastructures.MultiValueDictKeyError: 'JSC_district'\r, referer: http://10.99.99.201:8012/fd/education
[Thu Oct 13 15:03:26.612918 2022] [wsgi:error] [pid 7732:tid 1884] [client 192.168.101.70:56384] 01723513900\r, referer: http://10.99.99.201:8012/fd/files_upload
[Thu Oct 13 15:05:00.018833 2022] [wsgi:error] [pid 7732:tid 1884] [client 192.168.101.70:56418] 01723513900\r, referer: http://10.99.99.201:8012/fd/files_upload
[Thu Oct 13 15:05:03.226950 2022] [wsgi:error] [pid 7732:tid 1884] [client 192.168.101.70:56419] 01723513900\r, referer: http://10.99.99.201:8012/fd/scholarship_apply
